Workbook

Sheet Sheet2
C4: Me prepara uma tabela com todos os deals q fizeram, data, cheque pago, multiplo ebitda ou receita pago, receita na aquisicao CAGR desde a aquisicao e marcacao atual dos ativos
C6: vai me ajudar a entender eles pro almoco.

Sheet Sheet1
A1: Ref. Date | B1: 45901
Y2: AB - Marcações | Z2: AB - Marcações | AG2: AB - Marcações Mercado
B3: Investment | D3: Date | E3: Cost @FX | H3: FX | I3: Cost @BRL | J3: Stake | K3: Entry-EqV (post money R$) | L3: Pocket | N3: Entry Rev. | O3: Entry EBITDA | P3: Entry Debt | R3: Current Rev | S3: Current EBITDA | T3: Current Debt (net) | V3: Current Stake | Y3: NAV Relatri - Stake | Z3: NAV Relatri - Total | AA3: EV | AB3: EV/EBITDA | AC3: EV/Receita | AD3: MOIC | AE3: TIR | AG3: Equity Value | AH3: EV | AI3: EV/EBITDA | AJ3: EV/Receita | AK3: Comentários | AL3: Equity Value - Stake | AO3: Entry EV | AP3: EV/Rev | AR3: Entry EV (Dilution Adjusted) | AS3: EV/Rev | AU3: Revenue CAGR | AV3: Entry EBITDA | AW3: Current EBITDA | AY3: EV/Rev CAGR Adjusted | AZ3: EV/Current EBITDA | BB3: Fair EV/Receita | BC3: Implicit EV/EBITDA | BE3: MOIC | BF3: TIR | BH3: Exit Value | BJ3: On/Off Fundo I | BK3: Selected - Cost | BL3: Selected - Exit Value
B4: Bluefit | D4: 43252 | E4: 0.4 | F4: R$ | H4: 1 | I4: =+E4*H4 -> 0.4 | J4: 1 | K4: =+I4/J4 -> 0.4 | L4: Deal by Deal | N4: 88.4 | O4: N/A | P4: 0 | R4: 620 | S4: 115 | T4: -45 | V4: =6.07%+2.48% -> 0.0855 | Y4: - | Z4: - | AA4: - | AB4: - | AC4: - | AG4: 932 | AH4: =AG4+T4 -> 887 | AI4: =AH4/S4 -> 7.7130435 | AJ4: =AH4/R4 -> 1.4306452 | AK4: 8x EBITDA 2025 | AL4: - | AO4: =K4+P4 -> 0.4 | AP4: =+AO4/$N4 -> 0.0045248869 | AR4: =I4/V4+P4 -> 4.6783626 | AS4: =+AR4/$N4 -> 0.052922654 | AU4: =(R4/N4)^(1/YEARFRAC(D4,$B$1))-1 -> 0.30822155 | AV4: =O4 -> N/A | AW4: =+S4 -> 115 | AY4: =AR4/R4 -> 0.0075457461 | AZ4: =AR4/AW4 -> 0.040681414 | BB4: 1.5 | BC4: =BB4/(S4/R4) -> 8.0869565 | BE4: =(BB4*R4-T4)*V4/I4 -> 208.40625 | BF4: =BE4^(1/YEARFRAC(D4,$B$1))-1 -> 1.0885735 | BH4: =BE4*I4 -> 83.3625 | BJ4: 0 | BK4: =BJ4*I4 -> 0 | BL4: =BJ4*BH4 -> 0
Y5: - | Z5: - | AA5: - | AB5: - | AC5: - | AG5: - | AH5: - | AI5: - | AJ5: - | AL5: -
A6: Now part of Moove Inc. | B6: Kovi 1 | D6: 43617 | E6: 1.5 | F6: USD | H6: 3.85 | I6: =+E6*H6 -> 5.775 | J6: 0.0182 | K6: =+I6/J6 -> 317.30769 | L6: Deal by Deal | N6: 80.1 | O6: -17 | P6: 0 | R6: 661.2 | S6: 50 | T6: 0 | V6: 0.010747988 | Y6: - | Z6: - | AA6: - | AB6: - | AC6: - | AG6: 1588.4 | AH6: =AG6+T6 -> 1588.4 | AI6: =AH6/S6 -> 31.768 | AJ6: =AH6/R6 -> 2.4022989 | AK6: Valuation fusão | AL6: - | AO6: =K6+P6 -> 317.30769 | AP6: =+AO6/$N6 -> 3.9613944 | AR6: =I6/V6+P6 -> 537.30985 | AS6: =+AR6/$N6 -> 6.7079882 | AU6: =(R6/N6)^(1/YEARFRAC(D6,$B$1))-1 -> 0.4017548 | AV6: =O6 -> -17 | AW6: =+S6 -> 50 | AY6: =AR6/R6 -> 0.81262833 | AZ6: =AR6/AW6 -> 10.746197 | BB6: 2.5 | BC6: =BB6/(S6/R6) -> 33.06 | BE6: =(BB6*R6-T6)*V6/I6 -> 3.0764372 | BF6: =BE6^(1/YEARFRAC(D6,$B$1))-1 -> 0.19698219 | BH6: =BE6*I6 -> 17.766425 | BJ6: 0 | BK6: =BJ6*I6 -> 0 | BL6: =BJ6*BH6 -> 0
B7: Kovi 2 | D7: 43770 | E7: 1.3 | F7: USD | H7: 4.15 | I7: =+E7*H7 -> 5.395 | J7: 0.0115 | K7: =+I7/J7 -> 469.13043 | L7: Deal by Deal | N7: 80.1 | O7: -17 | P7: 0 | R7: 661.2 | S7: 50 | T7: 0 | V7: 0.0068158224 | Y7: - | Z7: - | AA7: - | AB7: - | AC7: - | AG7: - | AH7: - | AI7: - | AJ7: - | AL7: - | AO7: =K7+P7 -> 469.13043 | AP7: =+AO7/$N7 -> 5.8568094 | AR7: =I7/V7+P7 -> 791.54058 | AS7: =+AR7/$N7 -> 9.8819049 | AU7: =(R7/N7)^(1/YEARFRAC(D7,$B$1))-1 -> 0.43598078 | AV7: =O7 -> -17 | AW7: =+S7 -> 50 | AY7: =AR7/R7 -> 1.1971273 | AZ7: =AR7/AW7 -> 15.830812 | BB7: 2.5 | BC7: =BB7/(S7/R7) -> 33.06 | BE7: =(BB7*R7-T7)*V7/I7 -> 2.0883326 | BF7: =BE7^(1/YEARFRAC(D7,$B$1))-1 -> 0.13454781 | BH7: =BE7*I7 -> 11.266554 | BJ7: 0 | BK7: =BJ7*I7 -> 0 | BL7: =BJ7*BH7 -> 0
B8: Kovi 3 | D8: 44440 | E8: 2 | F8: USD | H8: 5.25 | I8: =+E8*H8 -> 10.5 | J8: 0.0051 | K8: =+I8/J8 -> 2058.8235 | L8: Deal by Deal | N8: 189.8 | O8: -57 | P8: 0 | R8: 661.2 | S8: 50 | T8: 0 | V8: 0.004512355 | Y8: - | Z8: - | AA8: - | AB8: - | AC8: - | AG8: - | AH8: - | AI8: - | AJ8: - | AL8: - | AO8: =K8+P8 -> 2058.8235 | AP8: =+AO8/$N8 -> 10.847332 | AR8: =I8/V8+P8 -> 2326.9446 | AS8: =+AR8/$N8 -> 12.259982 | AU8: =(R8/N8)^(1/YEARFRAC(D8,$B$1))-1 -> 0.36618389 | AV8: =O8 -> -57 | AW8: =+S8 -> 50 | AY8: =AR8/R8 -> 3.5192749 | AZ8: =AR8/AW8 -> 46.538891 | BB8: 2.5 | BC8: =BB8/(S8/R8) -> 33.06 | BE8: =(BB8*R8-T8)*V8/I8 -> 0.71037361 | BF8: =BE8^(1/YEARFRAC(D8,$B$1))-1 -> -0.081938649 | BH8: =BE8*I8 -> 7.4589229 | BJ8: 0 | BK8: =BJ8*I8 -> 0 | BL8: =BJ8*BH8 -> 0
Y9: - | Z9: - | AA9: - | AB9: - | AC9: - | AG9: - | AH9: - | AI9: - | AJ9: - | AL9: -
B10: The Coffee 1 | D10: 43770 | E10: 0.05 | F10: USD | H10: 4.15 | I10: =+E10*H10 -> 0.2075 | J10: 0.0167 | K10: =+I10/J10 -> 12.42515 | L10: Deal by Deal | N10: 1.7 | O10: -1 | P10: 0 | R10: 65 | S10: 5 | T10: 0 | V10: 0.0124 | Y10: - | Z10: - | AA10: - | AB10: - | AC10: - | AG10: 150 | AH10: =AG10+T10 -> 150 | AI10: =AH10/S10 -> 30 | AJ10: =AH10/R10 -> 2.3076923 | AK10: valuation abaixo de proposta atual | AL10: - | AO10: =K10+P10 -> 12.42515 | AP10: =+AO10/$N10 -> 7.3089116 | AR10: =I10/V10+P10 -> 16.733871 | AS10: =+AR10/$N10 -> 9.8434535 | AU10: =(R10/N10)^(1/YEARFRAC(D10,$B$1))-1 -> 0.86758173 | AV10: =O10 -> -1 | AW10: =+S10 -> 5 | AY10: =AR10/R10 -> 0.25744417 | AZ10: =AR10/AW10 -> 3.3467742 | BB10: 2 | BC10: =BB10/(S10/R10) -> 26 | BE10: =(BB10*R10-T10)*V10/I10 -> 7.7686747 | BF10: =BE10^(1/YEARFRAC(D10,$B$1))-1 -> 0.4211205 | BH10: =BE10*I10 -> 1.612 | BJ10: 0 | BK10: =BJ10*I10 -> 0 | BL10: =BJ10*BH10 -> 0
B11: The Coffee 2 | D11: 44136 | E11: 0.08 | F11: USD | H11: 5.45 | I11: =+E11*H11 -> 0.436 | J11: 0.0033 | K11: =+I11/J11 -> 132.12121 | L11: Deal by Deal | N11: 12.1 | O11: -4 | P11: 0 | R11: 65 | S11: 5 | T11: 0 | V11: 0.0031 | Y11: - | Z11: - | AA11: - | AB11: - | AC11: - | AG11: - | AH11: - | AI11: - | AJ11: - | AL11: - | AO11: =K11+P11 -> 132.12121 | AP11: =+AO11/$N11 -> 10.919108 | AR11: =I11/V11+P11 -> 140.64516 | AS11: =+AR11/$N11 -> 11.623567 | AU11: =(R11/N11)^(1/YEARFRAC(D11,$B$1))-1 -> 0.41599253 | AV11: =O11 -> -4 | AW11: =+S11 -> 5 | AY11: =AR11/R11 -> 2.1637717 | AZ11: =AR11/AW11 -> 28.129032 | BB11: 2 | BC11: =BB11/(S11/R11) -> 26 | BE11: =(BB11*R11-T11)*V11/I11 -> 0.92431193 | BF11: =BE11^(1/YEARFRAC(D11,$B$1))-1 -> -0.016152068 | BH11: =BE11*I11 -> 0.403 | BJ11: 0 | BK11: =BJ11*I11 -> 0 | BL11: =BJ11*BH11 -> 0
Y12: - | Z12: - | AA12: - | AB12: - | AC12: - | AG12: - | AH12: - | AI12: - | AJ12: - | AL12: -
B13: Atlas Agro | D13: 43983 | E13: 3.1 | F13: R$ | H13: 1 | I13: =+E13*H13 -> 3.1 | J13: 0.5 | K13: =+I13/J13 -> 6.2 | L13: Deal by Deal | N13: 20 | O13: 0.3 | P13: 2 | R13: 475.65 | S13: 70.332 | T13: 146 | V13: 0.3 | Y13: - | Z13: - | AA13: - | AB13: - | AC13: - | AG13: 462.656 | AH13: =AG13+T13 -> 608.656 | AI13: =AH13/S13 -> 8.6540408 | AJ13: =AH13/R13 -> 1.27963 | AK13: 8x EBITDA 2025 | AL13: - | AO13: =K13+P13 -> 8.2 | AP13: =+AO13/$N13 -> 0.41 | AR13: =I13/V13+P13 -> 12.333333 | AS13: =+AR13/$N13 -> 0.61666667 | AU13: =(R13/N13)^(1/YEARFRAC(D13,$B$1))-1 -> 0.82870767 | AV13: =O13 -> 0.3 | AW13: =+S13 -> 70.332 | AY13: =AR13/R13 -> 0.02592943 | AZ13: =AR13/AW13 -> 0.17535877 | BB13: 1 | BC13: =BB13/(S13/R13) -> 6.7629244 | BE13: =(BB13*R13-T13)*V13/I13 -> 31.901613 | BF13: =BE13^(1/YEARFRAC(D13,$B$1))-1 -> 0.9339289 | BH13: =BE13*I13 -> 98.895 | BJ13: 0 | BK13: =BJ13*I13 -> 0 | BL13: =BJ13*BH13 -> 0
Y14: - | Z14: - | AA14: - | AB14: - | AC14: - | AG14: - | AH14: - | AI14: - | AJ14: - | AL14: -
B15: Skelt 1 | D15: 44136 | E15: 2.9 | F15: USD | H15: =+H11 -> 5.45 | I15: =+E15*H15 -> 15.805 | J15: 0.2169 | K15: =+I15/J15 -> 72.867681 | L15: Co-Invest | N15: 36.8 | O15: 3 | P15: 2 | R15: 430 | S15: 55 | T15: 110 | V15: 0.18679528 | Y15: - | Z15: - | AA15: - | AB15: - | AC15: - | AG15: 950 | AH15: =AG15+T15 -> 1060 | AI15: =AH15/S15 -> 19.272727 | AJ15: =AH15/R15 -> 2.4651163 | AK15: valuation da proposta atual de M&A | AL15: =$AG$15*V15 -> 177.45552 | AO15: =K15+P15 -> 74.867681 | AP15: =+AO15/$N15 -> 2.0344479 | AR15: =I15/V15+P15 -> 86.611344 | AS15: =+AR15/$N15 -> 2.3535691 | AU15: =(R15/N15)^(1/YEARFRAC(D15,$B$1))-1 -> 0.66298001 | AV15: =O15 -> 3 | AW15: =+S15 -> 55 | AY15: =AR15/R15 -> 0.20142173 | AZ15: =AR15/AW15 -> 1.5747517 | BB15: 2 | BC15: =BB15/(S15/R15) -> 15.636364 | BE15: =(BB15*R15-T15)*V15/I15 -> 8.8640597 | BF15: =BE15^(1/YEARFRAC(D15,$B$1))-1 -> 0.57058676 | BH15: =BE15*I15 -> 140.09646 | BJ15: 0 | BK15: =BJ15*I15 -> 0 | BL15: =BJ15*BH15 -> 0
B16: Skelt 2 | D16: 44531 | E16: 2.4 | F16: USD | H16: 5.65 | I16: =+E16*H16 -> 13.56 | J16: 0.069 | K16: =+I16/J16 -> 196.52174 | L16: Co-Invest | N16: 54.1 | O16: -6 | P16: 9 | R16: 430 | S16: 55 | T16: 110 | V16: 0.062515184 | Y16: - | Z16: - | AA16: - | AB16: - | AC16: - | AG16: - | AH16: - | AI16: - | AJ16: - | AL16: =$AG$15*V16 -> 59.389425 | AO16: =K16+P16 -> 205.52174 | AP16: =+AO16/$N16 -> 3.7989231 | AR16: =I16/V16+P16 -> 225.9073 | AS16: =+AR16/$N16 -> 4.1757357 | AU16: =(R16/N16)^(1/YEARFRAC(D16,$B$1))-1 -> 0.73809023 | AV16: =O16 -> -6 | AW16: =+S16 -> 55 | AY16: =AR16/R16 -> 0.52536582 | AZ16: =AR16/AW16 -> 4.1074055 | BB16: 2 | BC16: =BB16/(S16/R16) -> 15.636364 | BE16: =(BB16*R16-T16)*V16/I16 -> 3.4576982 | BF16: =BE16^(1/YEARFRAC(D16,$B$1))-1 -> 0.39211963 | BH16: =BE16*I16 -> 46.886388 | BJ16: 0 | BK16: =BJ16*I16 -> 0 | BL16: =BJ16*BH16 -> 0
B17: Skelt 3 | D17: 45170 | E17: 13.5 | F17: R$ | H17: 1 | I17: =+E17*H17 -> 13.5 | J17: 0.088 | K17: =+I17/J17 -> 153.40909 | L17: Alpha I | N17: 114.8 | O17: 10 | P17: 10.5 | R17: 430 | S17: 55 | T17: 110 | V17: 0.0672 | Y17: 39.9 | Z17: =Y17/8.79% -> 453.92491 | AA17: =Z17+T17 -> 563.92491 | AB17: =AA17/S17 -> 10.25318 | AC17: =AA17/R17 -> 1.3114533 | AD17: =Y17/I17 -> 2.9555556 | AE17: =(AD17^(1/((45878-$D17)/365))-1) -> 0.74836359 | AG17: - | AH17: - | AI17: - | AJ17: - | AL17: =$AG$15*V17 -> 63.84 | AO17: =K17+P17 -> 163.90909 | AP17: =+AO17/$N17 -> 1.4277795 | AR17: =I17/V17+P17 -> 211.39286 | AS17: =+AR17/$N17 -> 1.8414012 | AU17: =(R17/N17)^(1/YEARFRAC(D17,$B$1))-1 -> 0.93536679 | AV17: =O17 -> 10 | AW17: =+S17 -> 55 | AY17: =AR17/R17 -> 0.4916113 | AZ17: =AR17/AW17 -> 3.8435065 | BB17: 2 | BC17: =BB17/(S17/R17) -> 15.636364 | BE17: =(BB17*R17-T17)*V17/I17 -> 3.7333333 | BF17: =BE17^(1/YEARFRAC(D17,$B$1))-1 -> 0.93218357 | BH17: =BE17*I17 -> 50.4 | BJ17: 1 | BK17: =BJ17*I17 -> 13.5 | BL17: =BJ17*BH17 -> 50.4
B18: Skelt 4 | D18: 45261 | E18: 2 | F18: USD | H18: 4.84 | I18: =+E18*H18 -> 9.68 | J18: 0.0615 | K18: =+I18/J18 -> 157.39837 | L18: Co-Invest | N18: 114.8 | O18: 10 | P18: 10.5 | R18: 430 | S18: 55 | T18: 110 | V18: 0.061819926 | Y18: - | Z18: - | AA18: - | AB18: - | AC18: - | AG18: - | AH18: - | AI18: - | AJ18: - | AL18: =$AG$15*V18 -> 58.728929 | AO18: =K18+P18 -> 167.89837 | AP18: =+AO18/$N18 -> 1.4625294 | AR18: =I18/V18+P18 -> 167.08382 | AS18: =+AR18/$N18 -> 1.455434 | AU18: =(R18/N18)^(1/YEARFRAC(D18,$B$1))-1 -> 1.1268138 | AV18: =O18 -> 10 | AW18: =+S18 -> 55 | AY18: =AR18/R18 -> 0.38856702 | AZ18: =AR18/AW18 -> 3.0378876 | BB18: 2 | BC18: =BB18/(S18/R18) -> 15.636364 | BE18: =(BB18*R18-T18)*V18/I18 -> 4.789767 | BF18: =BE18^(1/YEARFRAC(D18,$B$1))-1 -> 1.4476599 | BH18: =BE18*I18 -> 46.364944 | BJ18: 1 | BK18: =BJ18*I18 -> 9.68 | BL18: =BJ18*BH18 -> 46.364944
Y19: - | Z19: - | AA19: - | AB19: - | AC19: - | AG19: - | AH19: - | AI19: - | AJ19: - | AL19: -
B20: Paketá 1 | D20: 44166 | E20: 4 | F20: R$ | H20: 1 | I20: =+E20*H20 -> 4 | J20: 0.1026 | K20: =+I20/J20 -> 38.986355 | L20: Deal by Deal | N20: 3 | O20: -3 | P20: 0 | R20: 62.5 | S20: 28.6 | T20: 10 | V20: 0.064303185 | Y20: - | Z20: - | AA20: - | AB20: - | AC20: - | AG20: 271 | AH20: =AG20+T20 -> 281 | AI20: =AH20/S20 -> 9.8251748 | AJ20: =AH20/R20 -> 4.496 | AK20: 10x EBITDA 2025 | AL20: - | AO20: =K20+P20 -> 38.986355 | AP20: =+AO20/$N20 -> 12.995452 | AR20: =I20/V20+P20 -> 62.205317 | AS20: =+AR20/$N20 -> 20.735106 | AU20: =(R20/N20)^(1/YEARFRAC(D20,$B$1))-1 -> 0.89510564 | AV20: =O20 -> -3 | AW20: =+S20 -> 28.6 | AY20: =AR20/R20 -> 0.99528507 | AZ20: =AR20/AW20 -> 2.1750111 | BB20: 3 | BC20: =BB20/(S20/R20) -> 6.5559441 | BE20: =(BB20*R20-T20)*V20/I20 -> 2.8534538 | BF20: =BE20^(1/YEARFRAC(D20,$B$1))-1 -> 0.24700314 | BH20: =BE20*I20 -> 11.413815 | BJ20: 0 | BK20: =BJ20*I20 -> 0 | BL20: =BJ20*BH20 -> 0
B21: Paketá 2 | D21: 44501 | E21: 5 | F21: R$ | H21: 1 | I21: =+E21*H21 -> 5 | J21: 0.0427 | K21: =+I21/J21 -> 117.09602 | L21: Deal by Deal | N21: 4.3 | O21: -8 | P21: 0 | R21: 62.5 | S21: 28.6 | T21: 10 | V21: 0.036309748 | Y21: - | Z21: - | AA21: - | AB21: - | AC21: - | AG21: - | AH21: - | AI21: - | AJ21: - | AL21: - | AO21: =K21+P21 -> 117.09602 | AP21: =+AO21/$N21 -> 27.231632 | AR21: =I21/V21+P21 -> 137.70407 | AS21: =+AR21/$N21 -> 32.024202 | AU21: =(R21/N21)^(1/YEARFRAC(D21,$B$1))-1 -> 1.0101932 | AV21: =O21 -> -8 | AW21: =+S21 -> 28.6 | AY21: =AR21/R21 -> 2.2032651 | AZ21: =AR21/AW21 -> 4.8148275 | BB21: 3 | BC21: =BB21/(S21/R21) -> 6.5559441 | BE21: =(BB21*R21-T21)*V21/I21 -> 1.2889961 | BF21: =BE21^(1/YEARFRAC(D21,$B$1))-1 -> 0.06846742 | BH21: =BE21*I21 -> 6.4449803 | BJ21: 0 | BK21: =BJ21*I21 -> 0 | BL21: =BJ21*BH21 -> 0
Y22: - | Z22: - | AA22: - | AB22: - | AC22: - | AG22: - | AH22: - | AI22: - | AJ22: - | AL22: -
B23: TerraMagna 1 | D23: 44409 | E23: 5.4 | F23: USD | H23: 5.35 | I23: =+E23*H23 -> 28.89 | J23: 0.1463 | K23: =+I23/J23 -> 197.47095 | L23: Deal by Deal | N23: 4 | O23: -3 | P23: 0 | R23: 80 | S23: 30 | T23: 15 | V23: 0.11704 | Y23: - | Z23: - | AA23: - | AB23: - | AC23: - | AG23: 285 | AH23: =AG23+T23 -> 300 | AI23: =AH23/S23 -> 10 | AJ23: =AH23/R23 -> 3.75 | AK23: 10x EBITDA 2025 | AL23: - | AO23: =K23+P23 -> 197.47095 | AP23: =+AO23/$N23 -> 49.367738 | AR23: =I23/V23+P23 -> 246.83869 | AS23: =+AR23/$N23 -> 61.709672 | AU23: =(R23/N23)^(1/YEARFRAC(D23,$B$1))-1 -> 1.0826658 | AV23: =O23 -> -3 | AW23: =+S23 -> 30 | AY23: =AR23/R23 -> 3.0854836 | AZ23: =AR23/AW23 -> 8.2279563 | BB23: 3 | BC23: =BB23/(S23/R23) -> 8 | BE23: =(BB23*R23-T23)*V23/I23 -> 0.91152648 | BF23: =BE23^(1/YEARFRAC(D23,$B$1))-1 -> -0.02243064 | BH23: =BE23*I23 -> 26.334 | BJ23: 0 | BK23: =BJ23*I23 -> 0 | BL23: =BJ23*BH23 -> 0
B24: TerraMagna 2 | D24: 45658 | E24: 15 | F24: R$ | H24: 1 | I24: =+E24*H24 -> 15 | J24: 0.130435 | K24: =+I24/J24 -> 114.99981 | L24: Deal by Deal | N24: 31.5 | O24: 30 | P24: 20 | R24: 80 | S24: 30 | T24: 15 | V24: 0.130435 | Y24: - | Z24: - | AA24: - | AB24: - | AC24: - | AG24: - | AH24: - | AI24: - | AJ24: - | AL24: - | AO24: =K24+P24 -> 134.99981 | AP24: =+AO24/$N24 -> 4.2857082 | AR24: =I24/V24+P24 -> 134.99981 | AS24: =+AR24/$N24 -> 4.2857082 | AU24: =(R24/N24)^(1/YEARFRAC(D24,$B$1))-1 -> 3.047335 | AV24: =O24 -> 30 | AW24: =+S24 -> 30 | AY24: =AR24/R24 -> 1.6874976 | AZ24: =AR24/AW24 -> 4.4999936 | BB24: 3 | BC24: =BB24/(S24/R24) -> 8 | BE24: =(BB24*R24-T24)*V24/I24 -> 1.956525 | BF24: =BE24^(1/YEARFRAC(D24,$B$1))-1 -> 1.7367057 | BH24: =BE24*I24 -> 29.347875 | BJ24: 0 | BK24: =BJ24*I24 -> 0 | BL24: =BJ24*BH24 -> 0
Y25: - | Z25: - | AA25: - | AB25: - | AC25: - | AG25: - | AH25: - | AI25: - | AJ25: - | AL25: -
B26: Zerezes | D26: 44805 | E26: 12.5 | F26: R$ | H26: 1 | I26: =+E26*H26 -> 12.5 | J26: 0.0909 | K26: =+I26/J26 -> 137.51375 | L26: Alpha I | N26: 36 | O26: -1 | P26: 3 | R26: 140 | S26: 23 | T26: 7 | V26: 0.0909 | Y26: 19.4 | Z26: =Y26/9.09% -> 213.42134 | AA26: =Z26+T26 -> 220.42134 | AB26: =AA26/S26 -> 9.5835366 | AC26: =AA26/R26 -> 1.5744382 | AD26: =Y26/I26 -> 1.552 | AE26: =(AD26^(1/((45878-$D26)/365))-1) -> 0.16127535 | AG26: 225 | AH26: =AG26+T26 -> 232 | AI26: =AH26/S26 -> 10.086957 | AJ26: =AH26/R26 -> 1.6571429 | AK26: third party evaluation | AL26: =AG26*V26 -> 20.4525 | AO26: =K26+P26 -> 140.51375 | AP26: =+AO26/$N26 -> 3.9031598 | AR26: =I26/V26+P26 -> 140.51375 | AS26: =+AR26/$N26 -> 3.9031598 | AU26: =(R26/N26)^(1/YEARFRAC(D26,$B$1))-1 -> 0.57256466 | AV26: =O26 -> -1 | AW26: =+S26 -> 23 | AY26: =AR26/R26 -> 1.0036697 | AZ26: =AR26/AW26 -> 6.1092935 | BB26: 2.5 | BC26: =BB26/(S26/R26) -> 15.217391 | BE26: =(BB26*R26-T26)*V26/I26 -> 2.494296 | BF26: =BE26^(1/YEARFRAC(D26,$B$1))-1 -> 0.35617582 | BH26: =BE26*I26 -> 31.1787 | BJ26: 1 | BK26: =BJ26*I26 -> 12.5 | BL26: =BJ26*BH26 -> 31.1787
Y27: - | Z27: - | AA27: - | AB27: - | AC27: - | AG27: - | AH27: - | AI27: - | AJ27: - | AL27: -
B28: Regera 1 | D28: 45383 | E28: 12.5 | F28: R$ | H28: 1 | I28: =+E28*H28 -> 12.5 | J28: TBD | K28: N/A | L28: Alpha I | N28: 5 | O28: -8.919 | P28: 6.174 | R28: =3.325*4 -> 13.3 | S28: 5 | T28: 12 | V28: =+I28/(5*S28) -> 0.5 | Y28: 13 | Z28: =Y28/V28 -> 26 | AA28: =Z28+T28 -> 38 | AB28: =AA28/S28 -> 7.6 | AC28: =AA28/R28 -> 2.8571429 | AD28: =Y28/I28 -> 1.04 | AE28: =(AD28^(1/((45878-$D28)/365))-1) -> 0.029342577 | AG28: 47.142857 | AH28: =AG28+T28 -> 59.142857 | AI28: =AH28/S28 -> 11.828571 | AJ28: =AH28/R28 -> 4.4468314 | AK28: marcado a custo | AL28: =AG28*V28 -> 23.571429 | AO28: =5*AW28 -> 25 | AP28: =+AO28/$N28 -> 5 | AR28: =AO28 -> 25 | AS28: =+AR28/$N28 -> 5 | AU28: =(R28/N28)^(1/YEARFRAC(D28,$B$1))-1 -> 0.9948785 | AV28: =O28 -> -8.919 | AW28: =+S28 -> 5 | AY28: =AR28/R28 -> 1.8796992 | AZ28: =AR28/AW28 -> 5 | BB28: 3 | BC28: =BB28/(S28/R28) -> 7.98 | BE28: =(BB28*R28-T28)*V28/I28 -> 1.116 | BF28: =BE28^(1/YEARFRAC(D28,$B$1))-1 -> 0.08055111 | BH28: =BE28*I28 -> 13.95 | BJ28: 1 | BK28: =BJ28*I28 -> 12.5 | BL28: =BJ28*BH28 -> 13.95
B29: Regera 2 | D29: 45689 | E29: 3.5 | F29: R$ | H29: 1 | I29: =+E29*H29 -> 3.5 | J29: TBD | K29: N/A | L29: Co-Invest | N29: =2.138*4 -> 8.552 | O29: -4.1 | P29: 5.317 | R29: =3.325*4 -> 13.3 | S29: 5 | T29: 12 | V29: =+I29/(5*S29) -> 0.14 | Y29: - | Z29: - | AA29: - | AB29: - | AC29: - | AG29: - | AH29: - | AI29: - | AJ29: - | AL29: - | AO29: =5*AW29 -> 25 | AP29: =+AO29/$N29 -> 2.9232928 | AR29: =AO29 -> 25 | AS29: =+AR29/$N29 -> 2.9232928 | AU29: =(R29/N29)^(1/YEARFRAC(D29,$B$1))-1 -> 1.1319278 | AV29: =O29 -> -4.1 | AW29: =+S29 -> 5 | AY29: =AR29/R29 -> 1.8796992 | AZ29: =AR29/AW29 -> 5 | BB29: 3 | BC29: =BB29/(S29/R29) -> 7.98 | BE29: =(BB29*R29-T29)*V29/I29 -> 1.116 | BF29: =BE29^(1/YEARFRAC(D29,$B$1))-1 -> 0.20700772 | BH29: =BE29*I29 -> 3.906 | BJ29: 1 | BK29: =BJ29*I29 -> 3.5 | BL29: =BJ29*BH29 -> 3.906
Y30: - | Z30: - | AA30: - | AB30: - | AC30: - | AG30: - | AH30: - | AI30: - | AJ30: - | AL30: -
B31: Acquion 1 | D31: 45505 | E31: 12.5 | F31: R$ | H31: 1 | I31: =+E31*H31 -> 12.5 | J31: 0.37804772 | K31: =+I31/J31 -> 33.064609 | L31: Alpha I | N31: 16 | O31: -6 | P31: 50 | R31: =11.284*4 -> 45.136 | S31: 2 | T31: 37 | V31: 0.356 | Y31: 12.5 | Z31: =Y31/45.6% -> 27.412281 | AA31: =Z31+T31 -> 64.412281 | AB31: =AA31/S31 -> 32.20614 | AC31: =AA31/R31 -> 1.4270711 | AD31: =Y31/I31 -> 1 | AE31: =(AD31^(1/((45878-$D31)/365))-1) -> 0 | AG31: 33.064609 | AH31: =AG31+T31 -> 70.064609 | AI31: =AH31/S31 -> 35.032304 | AJ31: =AH31/R31 -> 1.5522999 | AK31: marcado a custo | AL31: =AG31*V31 -> 11.771001 | AO31: =K31+P31 -> 83.064609 | AP31: =+AO31/$N31 -> 5.1915381 | AR31: =I31/V31+P31 -> 85.11236 | AS31: =+AR31/$N31 -> 5.3195225 | AU31: =(R31/N31)^(1/YEARFRAC(D31,$B$1))-1 -> 1.6046939 | AV31: =O31 -> -6 | AW31: =+S31 -> 2 | AY31: =AR31/R31 -> 1.8856868 | AZ31: =AR31/AW31 -> 42.55618 | BB31: 2 | BC31: =BB31/(S31/R31) -> 45.136 | BE31: =(BB31*R31-T31)*V31/I31 -> 1.5171866 | BF31: =BE31^(1/YEARFRAC(D31,$B$1))-1 -> 0.46930823 | BH31: =BE31*I31 -> 18.964832 | BJ31: 1 | BK31: =BJ31*I31 -> 12.5 | BL31: =BJ31*BH31 -> 18.964832
B32: Acquion 2 | D32: 45748 | E32: 0.9 | F32: USD | H32: 5.85 | I32: =+E32*H32 -> 5.265 | J32: 0.14355228 | K32: =+I32/J32 -> 36.676533 | L32: Co-Invest | N32: 35 | O32: 2 | P32: 37 | R32: =11.284*4 -> 45.136 | S32: 2 | T32: 37 | V32: 0.14355228 | Y32: - | Z32: - | AA32: - | AB32: - | AC32: - | AG32: - | AH32: - | AI32: - | AJ32: - | AO32: =K32+P32 -> 73.676533 | AP32: =+AO32/$N32 -> 2.1050438 | AR32: =I32/V32+P32 -> 73.676533 | AS32: =+AR32/$N32 -> 2.1050438 | AU32: =(R32/N32)^(1/YEARFRAC(D32,$B$1))-1 -> 0.84116224 | AV32: =O32 -> 2 | AW32: =+S32 -> 2 | AY32: =AR32/R32 -> 1.6323231 | AZ32: =AR32/AW32 -> 36.838267 | BB32: 2 | BC32: =BB32/(S32/R32) -> 45.136 | BE32: =(BB32*R32-T32)*V32/I32 -> 1.4524819 | BF32: =BE32^(1/YEARFRAC(D32,$B$1))-1 -> 1.4494339 | BH32: =BE32*I32 -> 7.6473171 | BJ32: 1 | BK32: =BJ32*I32 -> 5.265 | BL32: =BJ32*BH32 -> 7.6473171
Y34: =SUM(Y4:Y32) -> 84.8 | Z34: =SUM(Z4:Z32) -> 720.75854 | AA34: =SUM(AA4:AA32) -> 886.75854 | AB34: =SUM(AB4:AB32) -> 59.642857 | AC34: =SUM(AC4:AC32) -> 7.1701054 | AD34: =SUM(AD4:AD32) -> 6.5475556 | AE34: =SUM(AE4:AE32) -> 0.93898151
B35: Subtotal | D35: - | I35: =SUBTOTAL(109,I4:I32) -> 177.5135 | J35: - | K35: =SUBTOTAL(109,K4:K32) -> 4252.4129 | L35: - | N35: =SUBTOTAL(109,N4:N32) -> 936.052 | O35: =SUBTOTAL(109,O4:O32) -> -80.719 | P35: =SUBTOTAL(109,P4:P32) -> 155.491 | R35: =SUBTOTAL(109,R4:R32) -> 5471.122 | S35: =SUBTOTAL(109,S4:S32) -> 719.532 | T35: =SUBTOTAL(109,T4:T32) -> 696 | V35: - | AO35: =SUBTOTAL(109,AO4:AO32) -> 4446.4129 | AP35: =+AO35/$N35 -> 4.7501773 | AR35: =SUBTOTAL(109,AR4:AR32) -> 5452.2316 | AS35: =+AR35/$N35 -> 5.8247101 | AU35: - | AV35: =SUBTOTAL(109,AV4:AV32) -> -80.719 | AW35: =SUBTOTAL(109,AW4:AW32) -> 719.532 | AY35: =AR35/R35 -> 0.99654725 | AZ35: =AR35/AW35 -> 7.5774692 | BB35: - | BC35: - | BE35: - | BF35: - | BH35: =SUBTOTAL(109,BH4:BH32) -> 653.69972 | BJ35: =SUBTOTAL(109,BJ4:BJ32) -> 7 | BK35: =SUBTOTAL(109,BK4:BK32) -> 69.445 | BL35: =SUBTOTAL(109,BL4:BL32) -> 172.41179
B36: Total | D36: - | I36: =SUM(I4:I32) -> 177.5135 | J36: - | K36: =SUM(K4:K32) -> 4252.4129 | L36: - | N36: =SUM(N4:N32) -> 936.052 | O36: =SUM(O4:O32) -> -80.719 | P36: =SUM(P4:P32) -> 155.491 | R36: =SUM(R4:R32) -> 5471.122 | S36: =SUM(S4:S32) -> 719.532 | T36: =SUM(T4:T32) -> 696 | V36: - | AO36: =SUM(AO4:AO32) -> 4446.4129 | AP36: =+AO36/$N36 -> 4.7501773 | AR36: =SUM(AR4:AR32) -> 5452.2316 | AS36: =+AR36/$N36 -> 5.8247101 | AU36: - | AV36: =SUM(AV4:AV32) -> -80.719 | AW36: =SUM(AW4:AW32) -> 719.532 | AY36: =AR36/R36 -> 0.99654725 | AZ36: =AR36/AW36 -> 7.5774692 | BB36: - | BC36: - | BE36: - | BF36: - | BH36: =SUM(BH4:BH32) -> 653.69972 | BJ36: =SUM(BJ4:BJ32) -> 7 | BK36: =SUM(BK4:BK32) -> 69.445 | BL36: =SUM(BL4:BL32) -> 172.41179
B37: Deal by Deal | D37: - | I37: =SUMIF($L$4:$L$32,$B37,I$4:I$32) -> 78.7035 | J37: - | K37: =SUMIF($L$4:$L$32,$B37,K$4:K$32) -> 3464.9612 | L37: - | N37: =SUMIF($L$4:$L$32,$B37,N$4:N$32) -> 515 | O37: =SUMIF($L$4:$L$32,$B37,O$4:O$32) -> -79.7 | P37: =SUMIF($L$4:$L$32,$B37,P$4:P$32) -> 22 | R37: =SUMIF($L$4:$L$32,$B37,R$4:R$32) -> 3494.25 | S37: =SUMIF($L$4:$L$32,$B37,S$4:S$32) -> 462.532 | T37: =SUMIF($L$4:$L$32,$B37,T$4:T$32) -> 151 | V37: - | AA37: 0.311 | AO37: =SUMIF($L$4:$L$32,$B37,AO$4:AO$32) -> 3486.9612 | AP37: =+AO37/$N37 -> 6.7707984 | AR37: =SUMIF($L$4:$L$32,$B37,AR$4:AR$32) -> 4411.9336 | AS37: =+AR37/$N37 -> 8.5668613 | AU37: - | AV37: =SUMIF($L$4:$L$32,$B37,AV$4:AV$32) -> -79.7 | AW37: =SUMIF($L$4:$L$32,$B37,AW$4:AW$32) -> 462.532 | AY37: =AR37/R37 -> 1.2626268 | AZ37: =AR37/AW37 -> 9.5386559 | BB37: - | BC37: - | BE37: - | BF37: - | BH37: =SUMIF($L$4:$L$32,$B37,BH$4:BH$32) -> 294.30507 | BJ37: =SUMIF($L$4:$L$32,$B37,BJ$4:BJ$32) -> 0 | BK37: =SUMIF($L$4:$L$32,$B37,BK$4:BK$32) -> 0 | BL37: =SUMIF($L$4:$L$32,$B37,BL$4:BL$32) -> 0
B38: Alpha I | D38: - | I38: =SUMIF($L$4:$L$32,$B38,I$4:I$32) -> 51 | J38: - | K38: =SUMIF($L$4:$L$32,$B38,K$4:K$32) -> 323.98745 | L38: - | N38: =SUMIF($L$4:$L$32,$B38,N$4:N$32) -> 171.8 | O38: =SUMIF($L$4:$L$32,$B38,O$4:O$32) -> -5.919 | P38: =SUMIF($L$4:$L$32,$B38,P$4:P$32) -> 69.674 | R38: =SUMIF($L$4:$L$32,$B38,R$4:R$32) -> 628.436 | S38: =SUMIF($L$4:$L$32,$B38,S$4:S$32) -> 85 | T38: =SUMIF($L$4:$L$32,$B38,T$4:T$32) -> 166 | V38: - | AO38: =SUMIF($L$4:$L$32,$B38,AO$4:AO$32) -> 412.48745 | AP38: =+AO38/$N38 -> 2.4009747 | AR38: =SUMIF($L$4:$L$32,$B38,AR$4:AR$32) -> 462.01897 | AS38: =+AR38/$N38 -> 2.6892839 | AU38: - | AV38: =SUMIF($L$4:$L$32,$B38,AV$4:AV$32) -> -5.919 | AW38: =SUMIF($L$4:$L$32,$B38,AW$4:AW$32) -> 85 | AY38: =AR38/R38 -> 0.73518858 | AZ38: =AR38/AW38 -> 5.4355173 | BB38: - | BC38: - | BE38: - | BF38: - | BH38: =SUMIF($L$4:$L$32,$B38,BH$4:BH$32) -> 114.49353 | BJ38: =SUMIF($L$4:$L$32,$B38,BJ$4:BJ$32) -> 4 | BK38: =SUMIF($L$4:$L$32,$B38,BK$4:BK$32) -> 51 | BL38: =SUMIF($L$4:$L$32,$B38,BL$4:BL$32) -> 114.49353
B39: Co-Invest | D39: - | I39: =SUMIF($L$4:$L$32,$B39,I$4:I$32) -> 47.81 | J39: - | K39: =SUMIF($L$4:$L$32,$B39,K$4:K$32) -> 463.46433 | L39: - | N39: =SUMIF($L$4:$L$32,$B39,N$4:N$32) -> 249.252 | O39: =SUMIF($L$4:$L$32,$B39,O$4:O$32) -> 4.9 | P39: =SUMIF($L$4:$L$32,$B39,P$4:P$32) -> 63.817 | R39: =SUMIF($L$4:$L$32,$B39,R$4:R$32) -> 1348.436 | S39: =SUMIF($L$4:$L$32,$B39,S$4:S$32) -> 172 | T39: =SUMIF($L$4:$L$32,$B39,T$4:T$32) -> 379 | V39: - | AO39: =SUMIF($L$4:$L$32,$B39,AO$4:AO$32) -> 546.96433 | AP39: =+AO39/$N39 -> 2.194423 | AR39: =SUMIF($L$4:$L$32,$B39,AR$4:AR$32) -> 578.279 | AS39: =+AR39/$N39 -> 2.3200576 | AU39: - | AV39: =SUMIF($L$4:$L$32,$B39,AV$4:AV$32) -> 4.9 | AW39: =SUMIF($L$4:$L$32,$B39,AW$4:AW$32) -> 172 | AY39: =AR39/R39 -> 0.42885165 | AZ39: =AR39/AW39 -> 3.3620872 | BB39: - | BC39: - | BE39: - | BF39: - | BH39: =SUMIF($L$4:$L$32,$B39,BH$4:BH$32) -> 244.90111 | BJ39: =SUMIF($L$4:$L$32,$B39,BJ$4:BJ$32) -> 3 | BK39: =SUMIF($L$4:$L$32,$B39,BK$4:BK$32) -> 18.445 | BL39: =SUMIF($L$4:$L$32,$B39,BL$4:BL$32) -> 57.918261
I41: =I38/90 -> 0.56666667
BL43: =MIN(D:D) -> 43252 | BM43: =EDATE(BL43,1) -> 43282 | BN43: =EDATE(BM43,1) -> 43313 | BO43: =EDATE(BN43,1) -> 43344 | BP43: =EDATE(BO43,1) -> 43374 | BQ43: =EDATE(BP43,1) -> 43405 | BR43: =EDATE(BQ43,1) -> 43435 | BS43: =EDATE(BR43,1) -> 43466 | BT43: =EDATE(BS43,1) -> 43497 | ... EX43: =EDATE(EW43,1) -> 45992
...

Sheet Output
B2: x | C2: Todos os Deals (Contas Excluem Bluefit)
E4: BRL '000 | H4: Stake Entrada | I4: Stake Hoje
C5: Empresa | D5: Data Investimento | E5: Custo | F5: Receita | G5: EBITDA | H5: EV/Receita | I5: EV/Receita | J5: Rev. CAGR | K5: Type
C6: Bluefit | D6: =Sheet1!D4 -> 43252 | E6: =Sheet1!I4*1000 -> 400 | F6: =Sheet1!N4 -> 88.4 | G6: =Sheet1!O4 -> N/A | H6: =Sheet1!AP4 -> 0.0045248869 | I6: =Sheet1!AS4 -> 0.052922654 | J6: =Sheet1!AU4 -> 0.30822155 | K6: Co-Inv
C8: Kovi 1 | D8: =Sheet1!D6 -> 43617 | E8: =Sheet1!I6*1000 -> 5775 | F8: =Sheet1!N6 -> 80.1 | G8: =Sheet1!O6 -> -17 | H8: =Sheet1!AP6 -> 3.9613944 | I8: =Sheet1!AS6 -> 6.7079882 | J8: =Sheet1!AU6 -> 0.4017548 | K8: Co-Inv
C9: Kovi 2 | D9: =Sheet1!D7 -> 43770 | E9: =Sheet1!I7*1000 -> 5395 | F9: =Sheet1!N7 -> 80.1 | G9: =Sheet1!O7 -> -17 | H9: =Sheet1!AP7 -> 5.8568094 | I9: =Sheet1!AS7 -> 9.8819049 | J9: =Sheet1!AU7 -> 0.43598078 | K9: Co-Inv
C10: Kovi 3 | D10: =Sheet1!D8 -> 44440 | E10: =Sheet1!I8*1000 -> 10500 | F10: =Sheet1!N8 -> 189.8 | G10: =Sheet1!O8 -> -57 | H10: =Sheet1!AP8 -> 10.847332 | I10: =Sheet1!AS8 -> 12.259982 | J10: =Sheet1!AU8 -> 0.36618389 | K10: Co-Inv
C11: The Coffee 1 | D11: =Sheet1!D10 -> 43770 | E11: =Sheet1!I10*1000 -> 207.5 | F11: =Sheet1!N10 -> 1.7 | G11: =Sheet1!O10 -> -1 | H11: =Sheet1!AP10 -> 7.3089116 | I11: =Sheet1!AS10 -> 9.8434535 | J11: =Sheet1!AU10 -> 0.86758173 | K11: Co-Inv
C12: The Coffee 2 | D12: =Sheet1!D11 -> 44136 | E12: =Sheet1!I11*1000 -> 436 | F12: =Sheet1!N11 -> 12.1 | G12: =Sheet1!O11 -> -4 | H12: =Sheet1!AP11 -> 10.919108 | I12: =Sheet1!AS11 -> 11.623567 | J12: =Sheet1!AU11 -> 0.41599253 | K12: Co-Inv
C13: Atlas Agro | D13: =Sheet1!D13 -> 43983 | E13: =Sheet1!I13*1000 -> 3100 | F13: =Sheet1!N13 -> 20 | G13: =Sheet1!O13 -> 0.3 | H13: =Sheet1!AP13 -> 0.41 | I13: =Sheet1!AS13 -> 0.61666667 | J13: =Sheet1!AU13 -> 0.82870767 | K13: Co-Inv
C14: Skelt 1 | D14: =Sheet1!D15 -> 44136 | E14: =Sheet1!I15*1000 -> 15805 | F14: =Sheet1!N15 -> 36.8 | G14: =Sheet1!O15 -> 3 | H14: =Sheet1!AP15 -> 2.0344479 | I14: =Sheet1!AS15 -> 2.3535691 | J14: =Sheet1!AU15 -> 0.66298001 | K14: Co-Inv
C15: Skelt 2 | D15: =Sheet1!D16 -> 44531 | E15: =Sheet1!I16*1000 -> 13560 | F15: =Sheet1!N16 -> 54.1 | G15: =Sheet1!O16 -> -6 | H15: =Sheet1!AP16 -> 3.7989231 | I15: =Sheet1!AS16 -> 4.1757357 | J15: =Sheet1!AU16 -> 0.73809023 | K15: Co-Inv
C16: Skelt 3 | D16: =Sheet1!D17 -> 45170 | E16: =Sheet1!I17*1000 -> 13500 | F16: =Sheet1!N17 -> 114.8 | G16: =Sheet1!O17 -> 10 | H16: =Sheet1!AP17 -> 1.4277795 | I16: =Sheet1!AS17 -> 1.8414012 | J16: =Sheet1!AU17 -> 0.93536679 | K16: Fund
C17: Skelt 4 | D17: =Sheet1!D18 -> 45261 | E17: =Sheet1!I18*1000 -> 9680 | F17: =Sheet1!N18 -> 114.8 | G17: =Sheet1!O18 -> 10 | H17: =Sheet1!AP18 -> 1.4625294 | I17: =Sheet1!AS18 -> 1.455434 | J17: =Sheet1!AU18 -> 1.1268138 | K17: Fund
C18: Paketá 1 | D18: =Sheet1!D20 -> 44166 | E18: =Sheet1!I20*1000 -> 4000 | F18: =Sheet1!N20 -> 3 | G18: =Sheet1!O20 -> -3 | H18: =Sheet1!AP20 -> 12.995452 | I18: =Sheet1!AS20 -> 20.735106 | J18: =Sheet1!AU20 -> 0.89510564 | K18: Co-Inv
C19: Paketá 2 | D19: =Sheet1!D21 -> 44501 | E19: =Sheet1!I21*1000 -> 5000 | F19: =Sheet1!N21 -> 4.3 | G19: =Sheet1!O21 -> -8 | H19: =Sheet1!AP21 -> 27.231632 | I19: =Sheet1!AS21 -> 32.024202 | J19: =Sheet1!AU21 -> 1.0101932 | K19: Co-Inv
C20: TerraMagna 1 | D20: =Sheet1!D23 -> 44409 | E20: =Sheet1!I23*1000 -> 28890 | F20: =Sheet1!N23 -> 4 | G20: =Sheet1!O23 -> -3 | H20: =Sheet1!AP23 -> 49.367738 | I20: =Sheet1!AS23 -> 61.709672 | J20: =Sheet1!AU23 -> 1.0826658 | K20: Co-Inv
C21: TerraMagna 2 | D21: =Sheet1!D24 -> 45658 | E21: =Sheet1!I24*1000 -> 15000 | F21: =Sheet1!N24 -> 31.5 | G21: =Sheet1!O24 -> 30 | H21: =Sheet1!AP24 -> 4.2857082 | I21: =Sheet1!AS24 -> 4.2857082 | J21: =Sheet1!AU24 -> 3.047335 | K21: Fund
C22: Zerezes | D22: =Sheet1!D26 -> 44805 | E22: =Sheet1!I26*1000 -> 12500 | F22: =Sheet1!N26 -> 36 | G22: =Sheet1!O26 -> -1 | H22: =Sheet1!AP26 -> 3.9031598 | I22: =Sheet1!AS26 -> 3.9031598 | J22: =Sheet1!AU26 -> 0.57256466 | K22: Fund
C23: Regera 1 | D23: =Sheet1!D28 -> 45383 | E23: =Sheet1!I28*1000 -> 12500 | F23: =Sheet1!N28 -> 5 | G23: =Sheet1!O28 -> -8.919 | H23: =Sheet1!AP28 -> 5 | I23: =Sheet1!AS28 -> 5 | J23: =Sheet1!AU28 -> 0.9948785 | K23: Fund
C24: Regera 2 | D24: =Sheet1!D29 -> 45689 | E24: =Sheet1!I29*1000 -> 3500 | F24: =Sheet1!N29 -> 8.552 | G24: =Sheet1!O29 -> -4.1 | H24: =Sheet1!AP29 -> 2.9232928 | I24: =Sheet1!AS29 -> 2.9232928 | J24: =Sheet1!AU29 -> 1.1319278 | K24: Fund
C25: Acquion 1 | D25: =Sheet1!D31 -> 45505 | E25: =Sheet1!I31*1000 -> 12500 | F25: =Sheet1!N31 -> 16 | G25: =Sheet1!O31 -> -6 | H25: =Sheet1!AP31 -> 5.1915381 | I25: =Sheet1!AS31 -> 5.3195225 | J25: =Sheet1!AU31 -> 1.6046939 | K25: Fund
C26: Acquion 2 | D26: =Sheet1!D32 -> 45748 | E26: =Sheet1!I32*1000 -> 5265 | F26: =Sheet1!N32 -> 35 | G26: =Sheet1!O32 -> 2 | H26: =Sheet1!AP32 -> 2.1050438 | I26: =Sheet1!AS32 -> 2.1050438 | J26: =Sheet1!AU32 -> 0.84116224 | K26: Fund
C28: Média | H28: =AVERAGE(H8:H26) -> 8.4753052 | I28: =AVERAGE(I8:I26) -> 10.461337 | J28: =AVERAGE(J8:J26) -> 0.94526205
C29: Mediana | H29: =MEDIAN(H8:H26) -> 4.2857082 | I29: =MEDIAN(I8:I26) -> 5 | J29: =MEDIAN(J8:J26) -> 0.86758173
C30: Media Ponderada | H30: =SUMPRODUCT($E$8:$E$26,H8:H26)/SUM($E$8:$E$26) -> 12.247388 | I30: =SUMPRODUCT($E$8:$E$26,I8:I26)/SUM($E$8:$E$26) -> 14.972374 | J30: =SUMPRODUCT($E$8:$E$26,J8:J26)/SUM($E$8:$E$26) -> 1.0678536
B32: x | C32: Somente Fundo
E34: BRL '000 | H34: Stake Entrada | I34: Stake Hoje
C35: Empresa | D35: Data Investimento | E35: Custo | F35: Receita | G35: EBITDA | H35: EV/Receita | I35: EV/Receita | J35: Rev. CAGR
C36: Skelt 3 | D36: =OFFSET(D$8,MATCH($C36,$C$8:$C$26,0)-1,0) -> 45170 | E36: =OFFSET(E$8,MATCH($C36,$C$8:$C$26,0)-1,0) -> 13500 | F36: =OFFSET(F$8,MATCH($C36,$C$8:$C$26,0)-1,0) -> 114.8 | G36: =OFFSET(G$8,MATCH($C36,$C$8:$C$26,0)-1,0) -> 10 | H36: =OFFSET(H$8,MATCH($C36,$C$8:$C$26,0)-1,0) -> 1.4277795 | I36: =OFFSET(I$8,MATCH($C36,$C$8:$C$26,0)-1,0) -> 1.8414012 | J36: =OFFSET(J$8,MATCH($C36,$C$8:$C$26,0)-1,0) -> 0.93536679
C37: Skelt 4 | D37: =OFFSET(D$8,MATCH($C37,$C$8:$C$26,0)-1,0) -> 45261 | E37: =OFFSET(E$8,MATCH($C37,$C$8:$C$26,0)-1,0) -> 9680 | F37: =OFFSET(F$8,MATCH($C37,$C$8:$C$26,0)-1,0) -> 114.8 | G37: =OFFSET(G$8,MATCH($C37,$C$8:$C$26,0)-1,0) -> 10 | H37: =OFFSET(H$8,MATCH($C37,$C$8:$C$26,0)-1,0) -> 1.4625294 | I37: =OFFSET(I$8,MATCH($C37,$C$8:$C$26,0)-1,0) -> 1.455434 | J37: =OFFSET(J$8,MATCH($C37,$C$8:$C$26,0)-1,0) -> 1.1268138
C38: TerraMagna 2 | D38: =OFFSET(D$8,MATCH($C38,$C$8:$C$26,0)-1,0) -> 45658 | E38: =OFFSET(E$8,MATCH($C38,$C$8:$C$26,0)-1,0) -> 15000 | F38: =OFFSET(F$8,MATCH($C38,$C$8:$C$26,0)-1,0) -> 31.5 | G38: =OFFSET(G$8,MATCH($C38,$C$8:$C$26,0)-1,0) -> 30 | H38: =OFFSET(H$8,MATCH($C38,$C$8:$C$26,0)-1,0) -> 4.2857082 | I38: =OFFSET(I$8,MATCH($C38,$C$8:$C$26,0)-1,0) -> 4.2857082 | J38: =OFFSET(J$8,MATCH($C38,$C$8:$C$26,0)-1,0) -> 3.047335
C39: Zerezes | D39: =OFFSET(D$8,MATCH($C39,$C$8:$C$26,0)-1,0) -> 44805 | E39: =OFFSET(E$8,MATCH($C39,$C$8:$C$26,0)-1,0) -> 12500 | F39: =OFFSET(F$8,MATCH($C39,$C$8:$C$26,0)-1,0) -> 36 | G39: =OFFSET(G$8,MATCH($C39,$C$8:$C$26,0)-1,0) -> -1 | H39: =OFFSET(H$8,MATCH($C39,$C$8:$C$26,0)-1,0) -> 3.9031598 | I39: =OFFSET(I$8,MATCH($C39,$C$8:$C$26,0)-1,0) -> 3.9031598 | J39: =OFFSET(J$8,MATCH($C39,$C$8:$C$26,0)-1,0) -> 0.57256466
C40: Regera 1 | D40: =OFFSET(D$8,MATCH($C40,$C$8:$C$26,0)-1,0) -> 45383 | E40: =OFFSET(E$8,MATCH($C40,$C$8:$C$26,0)-1,0) -> 12500 | F40: =OFFSET(F$8,MATCH($C40,$C$8:$C$26,0)-1,0) -> 5 | G40: =OFFSET(G$8,MATCH($C40,$C$8:$C$26,0)-1,0) -> -8.919 | H40: =OFFSET(H$8,MATCH($C40,$C$8:$C$26,0)-1,0) -> 5 | I40: =OFFSET(I$8,MATCH($C40,$C$8:$C$26,0)-1,0) -> 5 | J40: =OFFSET(J$8,MATCH($C40,$C$8:$C$26,0)-1,0) -> 0.9948785
C41: Regera 2 | D41: =OFFSET(D$8,MATCH($C41,$C$8:$C$26,0)-1,0) -> 45689 | E41: =OFFSET(E$8,MATCH($C41,$C$8:$C$26,0)-1,0) -> 3500 | F41: =OFFSET(F$8,MATCH($C41,$C$8:$C$26,0)-1,0) -> 8.552 | G41: =OFFSET(G$8,MATCH($C41,$C$8:$C$26,0)-1,0) -> -4.1 | H41: =OFFSET(H$8,MATCH($C41,$C$8:$C$26,0)-1,0) -> 2.9232928 | I41: =OFFSET(I$8,MATCH($C41,$C$8:$C$26,0)-1,0) -> 2.9232928 | J41: =OFFSET(J$8,MATCH($C41,$C$8:$C$26,0)-1,0) -> 1.1319278
C42: Acquion 1 | D42: =OFFSET(D$8,MATCH($C42,$C$8:$C$26,0)-1,0) -> 45505 | E42: =OFFSET(E$8,MATCH($C42,$C$8:$C$26,0)-1,0) -> 12500 | F42: =OFFSET(F$8,MATCH($C42,$C$8:$C$26,0)-1,0) -> 16 | G42: =OFFSET(G$8,MATCH($C42,$C$8:$C$26,0)-1,0) -> -6 | H42: =OFFSET(H$8,MATCH($C42,$C$8:$C$26,0)-1,0) -> 5.1915381 | I42: =OFFSET(I$8,MATCH($C42,$C$8:$C$26,0)-1,0) -> 5.3195225 | J42: =OFFSET(J$8,MATCH($C42,$C$8:$C$26,0)-1,0) -> 1.6046939
C43: Acquion 2 | D43: =OFFSET(D$8,MATCH($C43,$C$8:$C$26,0)-1,0) -> 45748 | E43: =OFFSET(E$8,MATCH($C43,$C$8:$C$26,0)-1,0) -> 5265 | F43: =OFFSET(F$8,MATCH($C43,$C$8:$C$26,0)-1,0) -> 35 | G43: =OFFSET(G$8,MATCH($C43,$C$8:$C$26,0)-1,0) -> 2 | H43: =OFFSET(H$8,MATCH($C43,$C$8:$C$26,0)-1,0) -> 2.1050438 | I43: =OFFSET(I$8,MATCH($C43,$C$8:$C$26,0)-1,0) -> 2.1050438 | J43: =OFFSET(J$8,MATCH($C43,$C$8:$C$26,0)-1,0) -> 0.84116224
C44: Total | E44: =SUM(E36:E43) -> 84445
C46: Média | H46: =AVERAGE(H36:H43) -> 3.2873814 | I46: =AVERAGE(I36:I43) -> 3.3541953 | J46: =AVERAGE(J36:J43) -> 1.2818428
C47: Mediana | H47: =MEDIAN(H36:H43) -> 3.4132263 | I47: =MEDIAN(I36:I43) -> 3.4132263 | J47: =MEDIAN(J36:J43) -> 1.0608461
...
