Workbook

Sheet Cover
B3: Complete Portfolio View
B8: Sheet Number | C8: Link to Sheet | F8: Format
B9: 1 | C9: Consolidated
B10: =B9+1 -> 2 | C10: Detailed | F10: Blue | G10: Inputs
B11: =B10+1 -> 3 | C11: Support - FX Rate
F12: Black | G12: Formulas
F14: Green | G14: References from other worksheets

Sheet 1- Consolidated
F3: In USD | M3: in BRL
B4: Cluster | F4: AuM at cost (US$ m) | G4: Allocated (US$ m) | H4: Holding period (years) | I4: Market Value (US$ m) | J4: MOIC (x) | K4: IRR (%) | M4: AuM at cost (R$ m) | N4: Allocated (R$ m) | O4: Holding period (years) | P4: Market Value (R$ m) | Q4: MOIC (x) | R4: IRR (%)
B6: Total | F6: =F8+F14 -> 35.643401 | G6: =G8+G14 -> 33.681169 | H6: ='2- Detailed'!X48 -> 2.9795641 | I6: =I8+I14 -> 142.94481 | J6: =I6/G6 -> 4.2440573 | K6: =(J6^(1/H6))-1 -> 0.62441003 | M6: =M8+M14 -> 255.1494 | N6: =N8+N14 -> 184.1494 | O6: ='2- Detailed'!X48 -> 2.9795641 | P6: =P8+P14 -> 786.19646 | Q6: =P6/N6 -> 4.2693403 | R6: =(Q6^(1/O6))-1 -> 0.62765143
C8: Vintage I | F8: ='2- Detailed'!K53 -> 17.94163 | G8: =G9+G10+G11+G12 -> 17.94163 | H8: ='2- Detailed'!X49 -> 4.3115087 | I8: =I9+I10+I11+I12+('2- Detailed'!F54/'2- Detailed'!E3) -> 102.56969 | J8: =I8/G8 -> 5.7168547 | K8: =(J8^(1/H8))-1 -> 0.4983492 | M8: ='2- Detailed'!K49 -> 98.402902 | N8: =N9+N10+N11+N12 -> 98.402902 | O8: ='2- Detailed'!X49 -> 4.3115087 | P8: =P9+P10+P11+P12+'2- Detailed'!F54 -> 564.13331 | Q8: =P8/N8 -> 5.732893 | R8: =(Q8^(1/O8))-1 -> 0.49932311
D9: 2018 | G9: ='2- Detailed'!AC8+'2- Detailed'!AC9 -> 0.10396631 | I9: ='2- Detailed'!AE8+'2- Detailed'!AE9 -> 14.488364 | N9: ='2- Detailed'!L8+'2- Detailed'!L9 -> 0.4 | P9: ='2- Detailed'!Y8+'2- Detailed'!Y9 -> 79.686
D10: 2019 | G10: ='2- Detailed'!AC11+'2- Detailed'!AC12+'2- Detailed'!AC15 -> 2.85 | I10: ='2- Detailed'!AE11+'2- Detailed'!AE12+'2- Detailed'!AE15 -> 5.4106103 | N10: ='2- Detailed'!L11+'2- Detailed'!L12+'2- Detailed'!L15 -> 15.675 | P10: ='2- Detailed'!Y11+'2- Detailed'!Y12+'2- Detailed'!Y15 -> 29.758357
D11: 2020 | G11: ='2- Detailed'!AC18+'2- Detailed'!AC20+'2- Detailed'!AC25+'2- Detailed'!AC16+('2- Detailed'!F49/'2- Detailed'!E3) -> 4.357155 | I11: ='2- Detailed'!AE18+'2- Detailed'!AE20+'2- Detailed'!AE25+'2- Detailed'!AE16 -> 60.753361 | N11: ='2- Detailed'!L18+'2- Detailed'!L20+'2- Detailed'!L25+'2- Detailed'!L16+'2- Detailed'!F49 -> 23.728524 | P11: ='2- Detailed'!Y18+'2- Detailed'!Y20+'2- Detailed'!Y25+'2- Detailed'!Y16 -> 334.14348
D12: 2021 | G12: ='2- Detailed'!AC13+'2- Detailed'!AC21+'2- Detailed'!AC26+'2- Detailed'!AC28 -> 10.630509 | I12: ='2- Detailed'!AE13+'2- Detailed'!AE21+'2- Detailed'!AE26+'2- Detailed'!AE28 -> 19.955126 | N12: ='2- Detailed'!L13+'2- Detailed'!L21+'2- Detailed'!L26+'2- Detailed'!L28 -> 58.599378 | P12: ='2- Detailed'!Y13+'2- Detailed'!Y21+'2- Detailed'!Y26+'2- Detailed'!Y28 -> 109.75319
C14: Vintage II | F14: ='2- Detailed'!K54 -> 17.701771 | G14: =G15+G16+G17+G18+G19 -> 15.739539 | H14: ='2- Detailed'!X50 -> 1.4510212 | I14: =I15+I16+I17+I18+('2- Detailed'!F55/'2- Detailed'!E3) -> 40.375119 | J14: =I14/G14 -> 2.5652034 | K14: =(J14^(1/H14))-1 -> 0.91405497 | M14: ='2- Detailed'!K50 -> 156.7465 | N14: =N15+N16+N17+N18+N19 -> 85.7465 | O14: ='2- Detailed'!X50 -> 1.4510212 | P14: =P15+P16+P17+P18+'2- Detailed'!F55 -> 222.06315 | Q14: =P14/N14 -> 2.5897635 | R14: =(Q14^(1/O14))-1 -> 0.92666582
D15: 2022 | G15: ='2- Detailed'!AC31 -> 2.3110273 | I15: ='2- Detailed'!AE31 -> 3.7186364 | N15: ='2- Detailed'!L31 -> 12.5 | P15: ='2- Detailed'!Y31 -> 20.4525
D16: 2023 | G16: ='2- Detailed'!AC22+'2- Detailed'!AC23 -> 4.6971949 | I16: ='2- Detailed'!AE22+'2- Detailed'!AE23 -> 22.28526 | N16: ='2- Detailed'!L22+'2- Detailed'!L23 -> 24.5 | P16: ='2- Detailed'!Y22+'2- Detailed'!Y23 -> 122.56893
D17: 2024 | G17: ='2- Detailed'!AC33+'2- Detailed'!AC36 -> 4.6188778 | I17: ='2- Detailed'!AE33+'2- Detailed'!AE36 -> 4.5454545 | N17: ='2- Detailed'!L33+'2- Detailed'!L36 -> 25 | P17: ='2- Detailed'!Y33+'2- Detailed'!Y36 -> 25
D18: 2025 | G18: ='2- Detailed'!AC29+'2- Detailed'!AC34+'2- Detailed'!AC37 -> 4.1124388 | I18: ='2- Detailed'!AE29+'2- Detailed'!AE34+'2- Detailed'!AE37 -> 8.3491773 | N18: ='2- Detailed'!L29+'2- Detailed'!L34+'2- Detailed'!L37 -> 23.7465 | P18: ='2- Detailed'!Y29+'2- Detailed'!Y34+'2- Detailed'!Y37 -> 45.920475

Sheet 2- Detailed
B2: Date | E2: 45878
B3: FX Rate (USD/BRL) | E3: 5.5
E5: Investment Details | O5: Operational Performance | T5: Holding Period | X5: Returns in R$ | AC5: Returns in US$
E6: Date | F6: Year | G6: Vintage | H6: Category | I6: Currency | J6: FX on investment | K6: Investment Size | L6: Allocated at Cost | M6: Exposure | O6: Revenue CAGR since investment | P6: Gross Revenue 2025E | Q6: EBITDA 2025E | R6: Current ownership | T6: Average Holding Period | U6: Unitary Duration (vintage) | V6: Unitary Duration (total) | X6: Estimated current equity value | Y6: AuM at Market | Z6: MOIC | AA6: IRR | AC6: Allocated at Cost | AD6: Estimated current equity value | AE6: AuM at Market | AF6: MOIC | AG6: IRR | AI6: Multiplo EBITDA | AJ6: Multiplo Receita | AL6: NAV Relatri | AM6: MOIC | AN6: TIR
B7: Bluefit | L7: =L8+L9 -> 0.4 | O7: 0.33636802 | P7: 676.68148 | Q7: 129 | R7: =R8+R9 -> 0.0855 | T7: =SUMPRODUCT(T8:T9,$M$8:$M$9) -> 7.1945205 | X7: 932 | Y7: =Y8+Y9 -> 79.686 | Z7: =IFERROR(Y7/L7,0) -> 199.215 | AA7: =IFERROR(((Z7^(1/$T7))-1),0) -> 1.0873415 | AC7: =AC8+AC9 -> 0.10396631 | AD7: =X7/$E$3 -> 169.45455 | AE7: =AE8+AE9 -> 14.488364 | AF7: =IFERROR(AE7/AC7,0) -> 139.35633 | AG7: =IFERROR(((AF7^(1/$T7))-1),0) -> 0.98619635 | AI7: =IFERROR(X7/Q7,"-") -> 7.2248062 | AJ7: =IFERROR(X7/P7,"-") -> 1.3773097
C8: Bluefit 1 | E8: 43252 | F8: =YEAR(E8) -> 2018 | G8: Vintage I | H8: Club Deals & Propr. Invests. | I8: R$ | J8: =SUMIF('3- Support - FX rate'!$A$4:$A$90,'2- Detailed'!E8,'3- Support - FX rate'!$B$4:$B$90) -> 3.8474 | K8: 0.2 | L8: =IF(I8="USD",K8*$E$3,K8) -> 0.2 | M8: =L8/$L$7 -> 0.5 | R8: =6.07% -> 0.0607 | T8: =IF(($E$2-$E8)>0,($E$2-$E8)/365,0) -> 7.1945205 | U8: =T8*L8/IF(G8=$J$49,$L$49,$L$50) -> 0.014622578 | V8: =T8*L8/($L$49+$L$50) -> 0.0078137865 | X8: =X7 -> 932 | Y8: =IF($E8<=$E$2,$R8*X8,0) -> 56.5724 | Z8: =IFERROR(Y8/L8,0) -> 282.862 | AA8: =IFERROR(((Z8^(1/$T8))-1),0) -> 1.1915723 | AC8: =IF(I8="USD",K8,K8/J8) -> 0.051983157 | AD8: =AD7 -> 169.45455 | AE8: =IF($E8<=$E$2,$R8*AD8,0) -> 10.285891 | AF8: =IFERROR(AE8/AC8,0) -> 197.86968 | AG8: =IFERROR(((AF8^(1/$T8))-1),0) -> 1.0853765 | AI8: =IFERROR(X8/Q8,"-") -> - | AJ8: =IFERROR(X8/P8,"-") -> -
C9: Bluefit 2 | E9: 43252 | F9: =YEAR(E9) -> 2018 | G9: Vintage I | H9: Club Deals & Propr. Invests. | I9: R$ | J9: =SUMIF('3- Support - FX rate'!$A$4:$A$90,'2- Detailed'!E9,'3- Support - FX rate'!$B$4:$B$90) -> 3.8474 | K9: 0.2 | L9: =IF(I9="USD",K9*$E$3,K9) -> 0.2 | M9: =L9/$L$7 -> 0.5 | R9: =5%*(1-0.38)*80% -> 0.0248 | T9: =IF(($E$2-$E9)>0,($E$2-$E9)/365,0) -> 7.1945205 | U9: =T9*L9/IF(G9=$J$49,$L$49,$L$50) -> 0.014622578 | V9: =T9*L9/($L$49+$L$50) -> 0.0078137865 | X9: =X8 -> 932 | Y9: =IF($E9<=$E$2,$R9*X9,0) -> 23.1136 | Z9: =IFERROR(Y9/L9,0) -> 115.568 | AA9: =IFERROR(((Z9^(1/$T9))-1),0) -> 0.93518919 | AC9: =IF(I9="USD",K9,K9/J9) -> 0.051983157 | AD9: =AD8 -> 169.45455 | AE9: =IF($E9<=$E$2,$R9*AD9,0) -> 4.2024727 | AF9: =IFERROR(AE9/AC9,0) -> 80.842968 | AG9: =IFERROR(((AF9^(1/$T9))-1),0) -> 0.84141681 | AI9: =IFERROR(X9/Q9,"-") -> - | AJ9: =IFERROR(X9/P9,"-") -> -
B10: Kovi / Moove | L10: =L11+L12+L13 -> 26.4 | O10: 0.42161955 | P10: 661.2 | Q10: 50 | R10: =R11+R12+R13 -> 0.022076166 | T10: =SUMPRODUCT(T11:T13,$M$11:$M$13) -> 5.1414954 | X10: =288.8*E3 -> 1588.4 | Y10: =Y11+Y12+Y13 -> 35.065782 | Z10: =IFERROR(Y10/L10,0) -> 1.3282493 | AA10: =IFERROR(((Z10^(1/$T10))-1),0) -> 0.05676247 | AC10: =AC11+AC12+AC13 -> 4.8 | AD10: =X10/$E$3 -> 288.8 | AE10: =AE11+AE12+AE13 -> 6.3755967 | AF10: =IFERROR(AE10/AC10,0) -> 1.3282493 | AG10: =IFERROR(((AF10^(1/$T10))-1),0) -> 0.05676247 | AI10: =IFERROR(X10/Q10,"-") -> 31.768 | AJ10: =IFERROR(X10/P10,"-") -> 2.4022989
C11: Kovi 1 | E11: 43617 | F11: =YEAR(E11) -> 2019 | G11: Vintage I | H11: Club Deals & Propr. Invests. | I11: USD | J11: =SUMIF('3- Support - FX rate'!$A$4:$A$90,'2- Detailed'!E11,'3- Support - FX rate'!$B$4:$B$90) -> 3.83265 | K11: 1.5 | L11: =IF(I11="USD",K11*$E$3,K11) -> 8.25 | M11: =L11/$L$10 -> 0.3125 | R11: 0.010747988 | T11: =IF(($E$2-$E11)>0,($E$2-$E11)/365,0) -> 6.1945205 | U11: =T11*L11/IF(G11=$J$49,$L$49,$L$50) -> 0.51934235 | V11: =T11*L11/($L$49+$L$50) -> 0.27751811 | X11: =X10 -> 1588.4 | Y11: =IF($E11<=$E$2,$R11*X11,0) -> 17.072105 | Z11: =IFERROR(Y11/L11,0) -> 2.069346 | AA11: =IFERROR(((Z11^(1/$T11))-1),0) -> 0.12456843 | AC11: =IF(I11="USD",K11,K11/J11) -> 1.5 | AD11: =AD10 -> 288.8 | AE11: =IF($E11<=$E$2,$R11*AD11,0) -> 3.104019 | AF11: =IFERROR(AE11/AC11,0) -> 2.069346 | AG11: =IFERROR(((AF11^(1/$T11))-1),0) -> 0.12456843 | AI11: =IFERROR(X11/Q11,"-") -> - | AJ11: =IFERROR(X11/P11,"-") -> -
C12: Kovi 2 | E12: 43770 | F12: =YEAR(E12) -> 2019 | G12: Vintage I | H12: Club Deals & Propr. Invests. | I12: USD | J12: =SUMIF('3- Support - FX rate'!$A$4:$A$90,'2- Detailed'!E12,'3- Support - FX rate'!$B$4:$B$90) -> 4.2283 | K12: 1.3 | L12: =IF(I12="USD",K12*$E$3,K12) -> 7.15 | M12: =L12/$L$10 -> 0.27083333 | R12: 0.0068158224 | T12: =IF(($E$2-$E12)>0,($E$2-$E12)/365,0) -> 5.7753425 | U12: =T12*L12/IF(G12=$J$49,$L$49,$L$50) -> 0.41963903 | V12: =T12*L12/($L$49+$L$50) -> 0.2242402 | X12: =X11 -> 1588.4 | Y12: =IF($E12<=$E$2,$R12*X12,0) -> 10.826252 | Z12: =IFERROR(Y12/L12,0) -> 1.5141612 | AA12: =IFERROR(((Z12^(1/$T12))-1),0) -> 0.074476155 | AC12: =IF(I12="USD",K12,K12/J12) -> 1.3 | AD12: =AD11 -> 288.8 | AE12: =IF($E12<=$E$2,$R12*AD12,0) -> 1.9684095 | AF12: =IFERROR(AE12/AC12,0) -> 1.5141612 | AG12: =IFERROR(((AF12^(1/$T12))-1),0) -> 0.074476155 | AI12: =IFERROR(X12/Q12,"-") -> - | AJ12: =IFERROR(X12/P12,"-") -> -
C13: Kovi 3 | E13: 44440 | F13: =YEAR(E13) -> 2021 | G13: Vintage I | H13: Club Deals & Propr. Invests. | I13: USD | J13: =SUMIF('3- Support - FX rate'!$A$4:$A$90,'2- Detailed'!E13,'3- Support - FX rate'!$B$4:$B$90) -> 5.4489 | K13: 2 | L13: =IF(I13="USD",K13*$E$3,K13) -> 11 | M13: =L13/$L$10 -> 0.41666667 | R13: 0.004512355 | T13: =IF(($E$2-$E13)>0,($E$2-$E13)/365,0) -> 3.939726 | U13: =T13*L13/IF(G13=$J$49,$L$49,$L$50) -> 0.44040354 | V13: =T13*L13/($L$49+$L$50) -> 0.23533601 | X13: =X12 -> 1588.4 | Y13: =IF($E13<=$E$2,$R13*X13,0) -> 7.1674248 | Z13: =IFERROR(Y13/L13,0) -> 0.65158407 | AA13: =IFERROR(((Z13^(1/$T13))-1),0) -> -0.10302343 | AC13: =IF(I13="USD",K13,K13/J13) -> 2 | AD13: =AD12 -> 288.8 | AE13: =IF($E13<=$E$2,$R13*AD13,0) -> 1.3031681 | AF13: =IFERROR(AE13/AC13,0) -> 0.65158407 | AG13: =IFERROR(((AF13^(1/$T13))-1),0) -> -0.10302343 | AI13: =IFERROR(X13/Q13,"-") -> - | AJ13: =IFERROR(X13/P13,"-") -> -
B14: The Coffee | L14: =L15+L16 -> 0.73315 | O14: 1.07 | P14: 65 | Q14: 5 | R14: =R15+R16 -> 0.0155 | T14: =SUMPRODUCT(T15:T16,$M$15:$M$16) -> 5.1487242 | X14: 150 | Y14: =Y15+Y16 -> 2.325 | Z14: =IFERROR(Y14/L14,0) -> 3.1712474 | AA14: =IFERROR(((Z14^(1/$T14))-1),0) -> 0.25126804 | AC14: =AC15+AC16 -> 0.1333 | AD14: =X14/$E$3 -> 27.272727 | AE14: =AE15+AE16 -> 0.42272727 | AF14: =IFERROR(AE14/AC14,0) -> 3.1712474 | AG14: =IFERROR(((AF14^(1/$T14))-1),0) -> 0.25126804 | AI14: =IFERROR(X14/Q14,"-") -> 30 | AJ14: =IFERROR(X14/P14,"-") -> 2.3076923
C15: The Coffee 1 | E15: 43770 | F15: =YEAR(E15) -> 2019 | G15: Vintage I | H15: Club Deals & Propr. Invests. | I15: USD | J15: =SUMIF('3- Support - FX rate'!$A$4:$A$90,'2- Detailed'!E15,'3- Support - FX rate'!$B$4:$B$90) -> 4.2283 | K15: 0.05 | L15: =IF(I15="USD",K15*$E$3,K15) -> 0.275 | M15: =L15/$L$14 -> 0.37509377 | R15: 0.0124 | T15: =IF(($E$2-$E15)>0,($E$2-$E15)/365,0) -> 5.7753425 | U15: =T15*L15/IF(G15=$J$49,$L$49,$L$50) -> 0.016139963 | V15: =T15*L15/($L$49+$L$50) -> 0.008624623 | X15: =X14 -> 150 | Y15: =IF($E15<=$E$2,$R15*X15,0) -> 1.86 | Z15: =IFERROR(Y15/L15,0) -> 6.7636364 | AA15: =IFERROR(((Z15^(1/$T15))-1),0) -> 0.39234106 | AC15: =IF(I15="USD",K15,K15/J15) -> 0.05 | AD15: =AD14 -> 27.272727 | AE15: =IF($E15<=$E$2,$R15*AD15,0) -> 0.33818182 | AF15: =IFERROR(AE15/AC15,0) -> 6.7636364 | AG15: =IFERROR(((AF15^(1/$T15))-1),0) -> 0.39234106 | AI15: =IFERROR(X15/Q15,"-") -> - | AJ15: =IFERROR(X15/P15,"-") -> -
C16: The Coffee 2 | E16: 44136 | F16: =YEAR(E16) -> 2020 | G16: Vintage I | H16: Club Deals & Propr. Invests. | I16: USD | J16: =SUMIF('3- Support - FX rate'!$A$4:$A$90,'2- Detailed'!E16,'3- Support - FX rate'!$B$4:$B$90) -> 5.38615 | K16: 0.0833 | L16: =IF(I16="USD",K16*$E$3,K16) -> 0.45815 | M16: =L16/$L$14 -> 0.62490623 | R16: 0.0031 | T16: =IF(($E$2-$E16)>0,($E$2-$E16)/365,0) -> 4.7726027 | U16: =T16*L16/IF(G16=$J$49,$L$49,$L$50) -> 0.022220564 | V16: =T16*L16/($L$49+$L$50) -> 0.01187388 | X16: =X15 -> 150 | Y16: =IF($E16<=$E$2,$R16*X16,0) -> 0.465 | Z16: =IFERROR(Y16/L16,0) -> 1.0149514 | AA16: =IFERROR(((Z16^(1/$T16))-1),0) -> 0.0031144143 | AC16: =IF(I16="USD",K16,K16/J16) -> 0.0833 | AD16: =AD15 -> 27.272727 | AE16: =IF($E16<=$E$2,$R16*AD16,0) -> 0.084545455 | AF16: =IFERROR(AE16/AC16,0) -> 1.0149514 | AG16: =IFERROR(((AF16^(1/$T16))-1),0) -> 0.0031144143 | AI16: =IFERROR(X16/Q16,"-") -> - | AJ16: =IFERROR(X16/P16,"-") -> -
B17: Atlas Agro | L17: =L18 -> 0.2 | O17: 0.89 | P17: 475.65 | Q17: 70.332 | R17: =R18 -> 0.3 | T17: =SUMPRODUCT(T18,$M$18) -> 5.2638889 | X17: 462.656 | Y17: =Y18 -> 138.7968 | Z17: =IFERROR(Y17/L17,0) -> 693.984 | AA17: =IFERROR(((Z17^(1/$T17))-1),0) -> 2.4656239 | AC17: =AC18 -> 0.036424565 | AD17: =X17/$E$3 -> 84.119273 | AE17: =AE18 -> 25.235782 | AF17: =IFERROR(AE17/AC17,0) -> 692.82315 | AG17: =IFERROR(((AF17^(1/$T17))-1),0) -> 2.4645218 | AI17: =IFERROR(X17/Q17,"-") -> 6.5781721 | AJ17: =IFERROR(X17/P17,"-") -> 0.97268159
C18: Atlas Agro | E18: 43983 | F18: =YEAR(E18) -> 2020 | G18: Vintage I | H18: Club Deals & Propr. Invests. | I18: R$ | J18: =SUMIF('3- Support - FX rate'!$A$4:$A$90,'2- Detailed'!E18,'3- Support - FX rate'!$B$4:$B$90) -> 5.4908 | K18: 0.2 | L18: =IF(I18="USD",K18*$E$3,K18) -> 0.2 | M18: =L18/$L$17 -> 1 | R18: 0.3 | T18: =IF(($E$2-$E18)>0,($E$2-$E18)/360,0) -> 5.2638889 | U18: =T18*L18/IF(G18=$J$49,$L$49,$L$50) -> 0.010698646 | V18: =T18*L18/($L$49+$L$50) -> 0.0057169763 | X18: =X17 -> 462.656 | Y18: =IF($E18<=$E$2,$R18*X18,0) -> 138.7968 | Z18: =IFERROR(Y18/L18,0) -> 693.984 | AA18: =IFERROR(((Z18^(1/$T18))-1),0) -> 2.4656239 | AC18: =IF(I18="USD",K18,K18/J18) -> 0.036424565 | AD18: =AD17 -> 84.119273 | AE18: =IF($E18<=$E$2,$R18*AD18,0) -> 25.235782 | AF18: =IFERROR(AE18/AC18,0) -> 692.82315 | AG18: =IFERROR(((AF18^(1/$T18))-1),0) -> 2.4645218 | AI18: =IFERROR(X18/Q18,"-") -> - | AJ18: =IFERROR(X18/P18,"-") -> -
B19: Skelt | L19: =L20+L21+L23+L22 -> 53.469629 | O19: 0.64995819 | P19: 450 | Q19: 60 | R19: =R20+R21+R23+R22 -> 0.37833039 | T19: =SUMPRODUCT(T20:T23,$M$20:$M$23) -> 3.1664918 | X19: =950*1+563.924914675768*0 -> 950 | Y19: =Y20+Y21+Y23+Y22 -> 359.41387 | Z19: =IFERROR(Y19/L19,0) -> 6.7218322 | AA19: =IFERROR(((Z19^(1/$T19))-1),0) -> 0.82526667 | AC19: =AC20+AC21+AC23+AC22 -> 9.9644002 | AD19: =X19/$E$3 -> 172.72727 | AE19: =AE20+AE21+AE23+AE22 -> 65.347977 | AF19: =IFERROR(AE19/AC19,0) -> 6.5581446 | AG19: =IFERROR(((AF19^(1/$T19))-1),0) -> 0.81111105 | AI19: =IFERROR(X19/Q19,"-") -> 15.833333 | AJ19: =IFERROR(X19/P19,"-") -> 2.1111111
C20: Skelt 1 | E20: 44136 | F20: =YEAR(E20) -> 2020 | G20: Vintage I | H20: Club Deals & Propr. Invests. | I20: USD | J20: =SUMIF('3- Support - FX rate'!$A$4:$A$90,'2- Detailed'!E20,'3- Support - FX rate'!$B$4:$B$90) -> 5.38615 | K20: 2.8992988 | L20: =IF(I20="USD",K20*$E$3,K20) -> 15.946143 | M20: =L20/$L$19 -> 0.29822805 | R20: 0.18679528 | T20: =IF(($E$2-$E20)>0,($E$2-$E20)/365,0) -> 4.7726027 | U20: =T20*L20/IF(G20=$J$49,$L$49,$L$50) -> 0.77339799 | V20: =T20*L20/($L$49+$L$50) -> 0.41327643 | X20: =X19 -> 950 | Y20: =IF($E20<=$E$2,$R20*X20,0) -> 177.45552 | Z20: =IFERROR(Y20/L20,0) -> 11.128429 | AA20: =IFERROR(((Z20^(1/$T20))-1),0) -> 0.65675591 | AC20: =IF(I20="USD",K20,K20/J20) -> 2.8992988 | AD20: =AD19 -> 172.72727 | AE20: =IF($E20<=$E$2,$R20*AD20,0) -> 32.26464 | AF20: =IFERROR(AE20/AC20,0) -> 11.128429 | AG20: =IFERROR(((AF20^(1/$T20))-1),0) -> 0.65675591 | AI20: =IFERROR(X20/Q20,"-") -> - | AJ20: =IFERROR(X20/P20,"-") -> -
C21: Skelt 2 | E21: 44531 | F21: =YEAR(E21) -> 2021 | G21: Vintage I | H21: Club Deals & Propr. Invests. | I21: USD | J21: =SUMIF('3- Support - FX rate'!$A$4:$A$90,'2- Detailed'!E21,'3- Support - FX rate'!$B$4:$B$90) -> 5.57 | K21: 2.3679065 | L21: =IF(I21="USD",K21*$E$3,K21) -> 13.023486 | M21: =L21/$L$19 -> 0.24356791 | R21: 0.062515184 | T21: =IF(($E$2-$E21)>0,($E$2-$E21)/365,0) -> 3.690411 | U21: =T21*L21/IF(G21=$J$49,$L$49,$L$50) -> 0.4884207 | V21: =T21*L21/($L$49+$L$50) -> 0.26099468 | X21: =X20 -> 950 | Y21: =IF($E21<=$E$2,$R21*X21,0) -> 59.389425 | Z21: =IFERROR(Y21/L21,0) -> 4.5601789 | AA21: =IFERROR(((Z21^(1/$T21))-1),0) -> 0.50857181 | AC21: =IF(I21="USD",K21,K21/J21) -> 2.3679065 | AD21: =AD20 -> 172.72727 | AE21: =IF($E21<=$E$2,$R21*AD21,0) -> 10.798077 | AF21: =IFERROR(AE21/AC21,0) -> 4.5601789 | AG21: =IFERROR(((AF21^(1/$T21))-1),0) -> 0.50857181 | AI21: =IFERROR(X21/Q21,"-") -> - | AJ21: =IFERROR(X21/P21,"-") -> -
C22: Skelt 3 | E22: 45170 | F22: =YEAR(E22) -> 2023 | G22: Vintage II | H22: Shift Alpha I | I22: R$ | J22: =SUMIF('3- Support - FX rate'!$A$4:$A$90,'2- Detailed'!E22,'3- Support - FX rate'!$B$4:$B$90) -> 5.0052 | K22: 13.5 | L22: =IF(I22="USD",K22*$E$3,K22) -> 13.5 | M22: =L22/$L$19 -> 0.25247978 | R22: 0.0672 | T22: =IF(($E$2-$E22)>0,($E$2-$E22)/360,0) -> 1.9666667 | U22: =T22*L22/IF(G22=$J$49,$L$49,$L$50) -> 0.30963363 | V22: =T22*L22/($L$49+$L$50) -> 0.14417641 | X22: =X23 -> 950 | Y22: =IF($E22<=$E$2,$R22*X22,0) -> 63.84 | Z22: =IFERROR(Y22/L22,0) -> 4.7288889 | AA22: =IFERROR(((Z22^(1/$T22))-1),0) -> 1.2034229 | AC22: =IF(I22="USD",K22,K22/J22) -> 2.6971949 | AD22: =AD23 -> 172.72727 | AE22: =IF($E22<=$E$2,$R22*AD22,0) -> 11.607273 | AF22: =IFERROR(AE22/AC22,0) -> 4.3034608 | AG22: =IFERROR(((AF22^(1/$T22))-1),0) -> 1.1002948 | AI22: =IFERROR(X22/Q22,"-") -> - | AJ22: =IFERROR(X22/P22,"-") -> - | AL22: 39.9 | AM22: =AL22/L22 -> 2.9555556 | AN22: =IFERROR(((AM22^(1/$T22))-1),0) -> 0.73503416
C23: Skelt 4 | E23: 45261 | F23: =YEAR(E23) -> 2023 | G23: Vintage II | H23: Club Deals & Propr. Invests. | I23: USD | J23: =SUMIF('3- Support - FX rate'!$A$4:$A$90,'2- Detailed'!E23,'3- Support - FX rate'!$B$4:$B$90) -> 4.8576 | K23: 2 | L23: =IF(I23="USD",K23*$E$3,K23) -> 11 | M23: =L23/$L$19 -> 0.20572426 | R23: 0.061819926 | T23: =IF(($E$2-$E23)>0,($E$2-$E23)/365,0) -> 1.690411 | U23: =T23*L23/IF(G23=$J$49,$L$49,$L$50) -> 0.21685457 | V23: =T23*L23/($L$49+$L$50) -> 0.10097519 | X23: =X21 -> 950 | Y23: =IF($E23<=$E$2,$R23*X23,0) -> 58.728929 | Z23: =IFERROR(Y23/L23,0) -> 5.3389936 | AA23: =IFERROR(((Z23^(1/$T23))-1),0) -> 1.6936719 | AC23: =IF(I23="USD",K23,K23/J23) -> 2 | AD23: =AD21 -> 172.72727 | AE23: =IF($E23<=$E$2,$R23*AD23,0) -> 10.677987 | AF23: =IFERROR(AE23/AC23,0) -> 5.3389936 | AG23: =IFERROR(((AF23^(1/$T23))-1),0) -> 1.6936719 | AI23: =IFERROR(X23/Q23,"-") -> - | AJ23: =IFERROR(X23/P23,"-") -> -
B24: Paketá | L24: =L25+L26 -> 9 | O24: 0.84 | P24: 62.5 | Q24: 28.6 | R24: =R25+R26 -> 0.10061293 | T24: =SUMPRODUCT(T25:T26,$M$25:$M$26) -> 4.1805175 | X24: 271 | Y24: =Y25+Y26 -> 27.266105 | Z24: =IFERROR(Y24/L24,0) -> 3.0295672 | AA24: =IFERROR(((Z24^(1/$T24))-1),0) -> 0.30361265 | AC24: =AC25+AC26 -> 1.655257 | AD24: =X24/$E$3 -> 49.272727 | AE24: =AE25+AE26 -> 4.9574736 | AF24: =IFERROR(AE24/AC24,0) -> 2.9949873 | AG24: =IFERROR(((AF24^(1/$T24))-1),0) -> 0.30003781 | AI24: =IFERROR(X24/Q24,"-") -> 9.4755245 | AJ24: =IFERROR(X24/P24,"-") -> 4.336
C25: Paketá 1 | E25: 44166 | F25: =YEAR(E25) -> 2020 | G25: Vintage I | H25: Club Deals & Propr. Invests. | I25: R$ | J25: =SUMIF('3- Support - FX rate'!$A$4:$A$90,'2- Detailed'!E25,'3- Support - FX rate'!$B$4:$B$90) -> 5.1942 | K25: =(800*5)/1000 -> 4 | L25: =IF(I25="USD",K25*$E$3,K25) -> 4 | M25: =L25/$L$24 -> 0.44444444 | R25: 0.064303185 | T25: =IF(($E$2-$E25)>0,($E$2-$E25)/365,0) -> 4.690411 | U25: =T25*L25/IF(G25=$J$49,$L$49,$L$50) -> 0.19066149 | V25: =T25*L25/($L$49+$L$50) -> 0.10188273 | X25: =X24 -> 271 | Y25: =IF($E25<=$E$2,$R25*X25,0) -> 17.426163 | Z25: =IFERROR(Y25/L25,0) -> 4.3565408 | AA25: =IFERROR(((Z25^(1/$T25))-1),0) -> 0.36856562 | AC25: =IF(I25="USD",K25,K25/J25) -> 0.77008972 | AD25: =AD24 -> 49.272727 | AE25: =IF($E25<=$E$2,$R25*AD25,0) -> 3.1683933 | AF25: =IFERROR(AE25/AC25,0) -> 4.1143171 | AG25: =IFERROR(((AF25^(1/$T25))-1),0) -> 0.35197561 | AI25: =IFERROR(X25/Q25,"-") -> - | AJ25: =IFERROR(X25/P25,"-") -> -
C26: Paketá 2 | E26: 44501 | F26: =YEAR(E26) -> 2021 | G26: Vintage I | H26: Club Deals & Propr. Invests. | I26: R$ | J26: =SUMIF('3- Support - FX rate'!$A$4:$A$90,'2- Detailed'!E26,'3- Support - FX rate'!$B$4:$B$90) -> 5.64865 | K26: =(1000*5)/1000 -> 5 | L26: =IF(I26="USD",K26*$E$3,K26) -> 5 | M26: =L26/$L$24 -> 0.55555556 | R26: 0.036309748 | T26: =IF(($E$2-$E26)>0,($E$2-$E26)/365,0) -> 3.7726027 | U26: =T26*L26/IF(G26=$J$49,$L$49,$L$50) -> 0.19169164 | V26: =T26*L26/($L$49+$L$50) -> 0.10243321 | X26: =X25 -> 271 | Y26: =IF($E26<=$E$2,$R26*X26,0) -> 9.8399417 | Z26: =IFERROR(Y26/L26,0) -> 1.9679883 | AA26: =IFERROR(((Z26^(1/$T26))-1),0) -> 0.19656488 | AC26: =IF(I26="USD",K26,K26/J26) -> 0.88516725 | AD26: =AD25 -> 49.272727 | AE26: =IF($E26<=$E$2,$R26*AD26,0) -> 1.7890803 | AF26: =IFERROR(AE26/AC26,0) -> 2.0211777 | AG26: =IFERROR(((AF26^(1/$T26))-1),0) -> 0.20505335 | AI26: =IFERROR(X26/Q26,"-") -> - | AJ26: =IFERROR(X26/P26,"-") -> -
B27: TerraMagna | L27: =L28+L29 -> 44.575893 | O27: 0.62 | P27: 160 | Q27: 50 | R27: =R28+R29 -> 0.247475 | T27: =SUMPRODUCT(T28:T29,$M$28:$M$29) -> 2.8731659 | X27: 285 | Y27: =Y28+Y29 -> 70.530375 | Z27: =IFERROR(Y27/L27,0) -> 1.5822538 | AA27: =IFERROR(((Z27^(1/$T27))-1),0) -> 0.17316119 | AC27: =AC28+AC29 -> 7.9452686 | AD27: =X27/$E$3 -> 51.818182 | AE27: =AE28+AE29 -> 12.823705 | AF27: =IFERROR(AE27/AC27,0) -> 1.6140052 | AG27: =IFERROR(((AF27^(1/$T27))-1),0) -> 0.18130194 | AI27: =IFERROR(X27/Q27,"-") -> 5.7 | AJ27: =IFERROR(X27/P27,"-") -> 1.78125
C28: TerraMagna 1 | E28: 44409 | F28: =YEAR(E28) -> 2021 | G28: Vintage I | H28: Club Deals & Propr. Invests. | I28: USD | J28: =SUMIF('3- Support - FX rate'!$A$4:$A$90,'2- Detailed'!E28,'3- Support - FX rate'!$B$4:$B$90) -> 5.11955 | K28: 5.377435 | L28: =IF(I28="USD",K28*$E$3,K28) -> 29.575893 | M28: =L28/$L$27 -> 0.66349524 | R28: =14.63%*0.8 -> 0.11704 | T28: =IF(($E$2-$E28)>0,($E$2-$E28)/365,0) -> 4.0246575 | U28: =T28*L28/IF(G28=$J$49,$L$49,$L$50) -> 1.2096476 | V28: =T28*L28/($L$49+$L$50) -> 0.64639275 | X28: =X27 -> 285 | Y28: =IF($E28<=$E$2,$R28*X28,0) -> 33.3564 | Z28: =IFERROR(Y28/L28,0) -> 1.127824 | AA28: =IFERROR(((Z28^(1/$T28))-1),0) -> 0.030339413 | AC28: =IF(I28="USD",K28,K28/J28) -> 5.377435 | AD28: =AD27 -> 51.818182 | AE28: =IF($E28<=$E$2,$R28*AD28,0) -> 6.0648 | AF28: =IFERROR(AE28/AC28,0) -> 1.127824 | AG28: =IFERROR(((AF28^(1/$T28))-1),0) -> 0.030339413 | AI28: =IFERROR(X28/Q28,"-") -> - | AJ28: =IFERROR(X28/P28,"-") -> -
C29: TerraMagna 2 | E29: 45658 | F29: =YEAR(E29) -> 2025 | G29: Vintage II | H29: Club Deals & Propr. Invests. | I29: R$ | J29: =SUMIF('3- Support - FX rate'!$A$4:$A$90,'2- Detailed'!E29,'3- Support - FX rate'!$B$4:$B$90) -> 5.8415 | K29: 15 | L29: =IF(I29="USD",K29*$E$3,K29) -> 15 | M29: =L29/$L$27 -> 0.33650476 | R29: 0.130435 | T29: =IF(($E$2-$E29)>0,($E$2-$E29)/365,0) -> 0.60273973 | U29: =T29*L29/IF(G29=$J$49,$L$49,$L$50) -> 0.10543982 | V29: =T29*L29/($L$49+$L$50) -> 0.049096526 | X29: =X28 -> 285 | Y29: =IF($E29<=$E$2,$R29*X29,0) -> 37.173975 | Z29: =IFERROR(Y29/L29,0) -> 2.478265 | AA29: =IFERROR(((Z29^(1/$T29))-1),0) -> 3.5074087 | AC29: =IF(I29="USD",K29,K29/J29) -> 2.5678336 | AD29: =AD28 -> 51.818182 | AE29: =IF($E29<=$E$2,$R29*AD29,0) -> 6.7589045 | AF29: =IFERROR(AE29/AC29,0) -> 2.6321427 | AG29: =IFERROR(((AF29^(1/$T29))-1),0) -> 3.9811723 | AI29: =IFERROR(X29/Q29,"-") -> - | AJ29: =IFERROR(X29/P29,"-") -> -
B30: Zerezes | L30: =L31 -> 12.5 | O30: 0.57256466 | P30: 140 | Q30: 23 | R30: =R31 -> 0.0909 | T30: =SUMPRODUCT(T31,$M$31) -> 2.939726 | X30: 225 | Y30: =Y31 -> 20.4525 | Z30: =IFERROR(Y30/L30,0) -> 1.6362 | AA30: =IFERROR(((Z30^(1/$T30))-1),0) -> 0.18233418 | AC30: =AC31 -> 2.3110273 | AD30: =X30/$E$3 -> 40.909091 | AE30: =AE31 -> 3.7186364 | AF30: =IFERROR(AE30/AC30,0) -> 1.6090837 | AG30: =IFERROR(((AF30^(1/$T30))-1),0) -> 0.17563198 | AI30: =IFERROR(X30/Q30,"-") -> 9.7826087 | AJ30: =IFERROR(X30/P30,"-") -> 1.6071429
C31: Zerezes | E31: 44805 | F31: =YEAR(E31) -> 2022 | G31: Vintage II | H31: Shift Alpha I | I31: R$ | J31: =SUMIF('3- Support - FX rate'!$A$4:$A$90,'2- Detailed'!E31,'3- Support - FX rate'!$B$4:$B$90) -> 5.40885 | K31: 12.5 | L31: =IF(I31="USD",K31*$E$3,K31) -> 12.5 | M31: =L31/$L$30 -> 1 | R31: 0.0909 | T31: =IF(($E$2-$E31)>0,($E$2-$E31)/365,0) -> 2.939726 | U31: =T31*L31/IF(G31=$J$49,$L$49,$L$50) -> 0.42854898 | V31: =T31*L31/($L$49+$L$50) -> 0.19954762 | X31: =X30 -> 225 | Y31: =IF($E31<=$E$2,$R31*X31,0) -> 20.4525 | Z31: =IFERROR(Y31/L31,0) -> 1.6362 | AA31: =IFERROR(((Z31^(1/$T31))-1),0) -> 0.18233418 | AC31: =IF(I31="USD",K31,K31/J31) -> 2.3110273 | AD31: =AD30 -> 40.909091 | AE31: =IF($E31<=$E$2,$R31*AD31,0) -> 3.7186364 | AF31: =IFERROR(AE31/AC31,0) -> 1.6090837 | AG31: =IFERROR(((AF31^(1/$T31))-1),0) -> 0.17563198 | AI31: =IFERROR(X31/Q31,"-") -> - | AJ31: =IFERROR(X31/P31,"-") -> - | AL31: 19.4 | AM31: =AL31/L31 -> 1.552 | AN31: =IFERROR(((AM31^(1/$T31))-1),0) -> 0.16127535
B32: Regera | L32: =L34+L33 -> 16.5 | O32: 1.8 | P32: 14 | Q32: 5 | R32: =R34+R33 -> 0.35 | T32: =SUMPRODUCT(T33:T34,$M$33:$M$34) -> 1.1529265 | X32: 47.142857 | Y32: =Y34+Y33 -> 16.5 | Z32: =IFERROR(Y32/L32,0) -> 1 | AA32: N/A*** | AC32: =AC34+AC33 -> 3.0932893 | AD32: =X32/$E$3 -> 8.5714286 | AE32: =AE34+AE33 -> 3 | AF32: =IFERROR(AE32/AC32,0) -> 0.96984139 | AG32: N/A*** | AI32: =IFERROR(X32/Q32,"-") -> 9.4285714 | AJ32: =IFERROR(X32/P32,"-") -> 3.3673469
C33: Regera 1 | E33: 45383 | F33: =YEAR(E33) -> 2024 | G33: Vintage II | H33: Shift Alpha I | I33: R$ | J33: =SUMIF('3- Support - FX rate'!$A$4:$A$90,'2- Detailed'!E33,'3- Support - FX rate'!$B$4:$B$90) -> 5.1831 | K33: 12.5 | L33: =IF(I33="USD",K33*$E$3,K33) -> 12.5 | M33: =L33/$L$32 -> 0.75757576 | R33: 0.26515152 | T33: =IF(($E$2-$E33)>0,($E$2-$E33)/365,0) -> 1.3561644 | U33: =T33*L33/IF(G33=$J$49,$L$49,$L$50) -> 0.19769967 | V33: =T33*L33/($L$49+$L$50) -> 0.092055986 | X33: =X32 -> 47.142857 | Y33: =IF($E33<=$E$2,$R33*X33,0) -> 12.5 | Z33: =IFERROR(Y33/L33,0) -> 1 | AA33: N/A*** | AC33: =IF(I33="USD",K33,K33/J33) -> 2.4116841 | AD33: =AD32 -> 8.5714286 | AE33: =IF($E33<=$E$2,$R33*AD33,0) -> 2.2727273 | AF33: =IFERROR(AE33/AC33,0) -> 0.94238182 | AG33: N/A*** | AI33: =IFERROR(X33/Q33,"-") -> - | AJ33: =IFERROR(X33/P33,"-") -> - | AL33: 13 | AM33: =AL33/L33 -> 1.04 | AN33: =IFERROR(((AM33^(1/$T33))-1),0) -> 0.029342577
C34: Regera 2 | E34: 45689 | F34: =YEAR(E34) -> 2025 | G34: Vintage II | H34: Club Deals & Propr. Invests. | I34: R$ | J34: =SUMIF('3- Support - FX rate'!$A$4:$A$90,'2- Detailed'!E34,'3- Support - FX rate'!$B$4:$B$90) -> 5.8685 | K34: 4 | L34: =IF(I34="USD",K34*$E$3,K34) -> 4 | M34: =L34/$L$32 -> 0.24242424 | R34: 0.084848485 | T34: =IF(($E$2-$E34)>0,($E$2-$E34)/365,0) -> 0.51780822 | U34: =T34*L34/IF(G34=$J$49,$L$49,$L$50) -> 0.024155305 | V34: =T34*L34/($L$49+$L$50) -> 0.011247568 | X34: =X33 -> 47.142857 | Y34: =IF($E34<=$E$2,$R34*X34,0) -> 4 | Z34: =IFERROR(Y34/L34,0) -> 1 | AA34: N/A*** | AC34: =IF(I34="USD",K34,K34/J34) -> 0.68160518 | AD34: =AD33 -> 8.5714286 | AE34: =IF($E34<=$E$2,$R34*AD34,0) -> 0.72727273 | AF34: =IFERROR(AE34/AC34,0) -> 1.067 | AG34: N/A*** | AI34: =IFERROR(X34/Q34,"-") -> - | AJ34: =IFERROR(X34/P34,"-") -> -
B35: Acquion | L35: =L37+L36 -> 17.2465 | O35: 1.19 | P35: 35 | Q35: 2 | R35: =R37+R36 -> 0.5216 | T35: =SUMPRODUCT(T36:T37,$M$36:$M$37) -> 0.83869231 | X35: 33.064609 | Y35: =Y37+Y36 -> 17.2465 | Z35: =IFERROR(Y35/L35,0) -> 1 | AA35: N/A*** | AC35: =AC37+AC36 -> 3.0701937 | AD35: =X35/$E$3 -> 6.0117471 | AE35: =AE37+AE36 -> 3.1357273 | AF35: =IFERROR(AE35/AC35,0) -> 1.0213451 | AG35: N/A*** | AI35: =IFERROR(X35/Q35,"-") -> 16.532304 | AJ35: =IFERROR(X35/P35,"-") -> 0.94470311
C36: Acquion 1 | E36: 45505 | F36: =YEAR(E36) -> 2024 | G36: Vintage II | H36: Shift Alpha I | I36: R$ | J36: =SUMIF('3- Support - FX rate'!$A$4:$A$90,'2- Detailed'!E36,'3- Support - FX rate'!$B$4:$B$90) -> 5.6633 | K36: 12.5 | L36: =IF(I36="USD",K36*$E$3,K36) -> 12.5 | M36: =L36/$L$35 -> 0.72478474 | R36: 0.37804772 | T36: =IF(($E$2-$E36)>0,($E$2-$E36)/365,0) -> 1.0219178 | U36: =T36*L36/IF(G36=$J$49,$L$49,$L$50) -> 0.14897369 | V36: =T36*L36/($L$49+$L$50) -> 0.06936744 | X36: =X35 -> 33.064609 | Y36: =IF($E36<=$E$2,$R36*X36,0) -> 12.5 | Z36: =IFERROR(Y36/L36,0) -> 1 | AA36: N/A*** | AC36: =IF(I36="USD",K36,K36/J36) -> 2.2071937 | AD36: =AD35 -> 6.0117471 | AE36: =IF($E36<=$E$2,$R36*AD36,0) -> 2.2727273 | AF36: =IFERROR(AE36/AC36,0) -> 1.0296909 | AG36: N/A*** | AI36: =IFERROR(X36/Q36,"-") -> - | AJ36: =IFERROR(X36/P36,"-") -> - | AL36: 12.5 | AM36: =AL36/L36 -> 1 | AN36: =IFERROR(((AM36^(1/$T36))-1),0) -> 0
C37: Acquion 2 | E37: 45748 | F37: =YEAR(E37) -> 2025 | G37: Vintage II | H37: Club Deals & Propr. Invests. | I37: USD | J37: =SUMIF('3- Support - FX rate'!$A$4:$A$90,'2- Detailed'!E37,'3- Support - FX rate'!$B$4:$B$90) -> 5.6614 | K37: 0.863 | L37: =IF(I37="USD",K37*$E$3,K37) -> 4.7465 | M37: =L37/$L$35 -> 0.27521526 | R37: 0.14355228 | T37: =IF(($E$2-$E37)>0,($E$2-$E37)/365,0) -> 0.35616438 | U37: =T37*L37/IF(G37=$J$49,$L$49,$L$50) -> 0.01971549 | V37: =T37*L37/($L$49+$L$50) -> 0.0091802321 | X37: =X36 -> 33.064609 | Y37: =IF($E37<=$E$2,$R37*X37,0) -> 4.7465 | Z37: =IFERROR(Y37/L37,0) -> 1 | AA37: N/A*** | AC37: =IF(I37="USD",K37,K37/J37) -> 0.863 | AD37: =AD36 -> 6.0117471 | AE37: =IF($E37<=$E$2,$R37*AD37,0) -> 0.863 | AF37: =IFERROR(AE37/AC37,0) -> 1 | AG37: N/A*** | AI37: =IFERROR(X37/Q37,"-") -> - | AJ37: =IFERROR(X37/P37,"-") -> - | AL37: =SUM(AL7:AL36) -> 84.8
B38: Alpha I's 5th deal | L38: =L39 -> 12.5 | AI38: =IFERROR(X38/Q38,"-") -> - | AJ38: =IFERROR(X38/P38,"-") -> -
C39: Alpha's 5th deal | E39: 45962 | F39: =YEAR(E39) -> 2025 | G39: Vintage II | H39: Shift Alpha I | I39: R$ | K39: 12.5 | L39: =IF(I39="USD",K39*$E$3,K39) -> 12.5 | M39: =L39/$L$38 -> 1 | AI39: =IFERROR(X39/Q39,"-") -> - | AJ39: =IFERROR(X39/P39,"-") -> -
C40: Co-invest | E40: 45962 | F40: =YEAR(E40) -> 2025 | G40: Vintage II | H40: Club Deals & Propr. Invests. | I40: R$ | K40: 15 | L40: =IF(I40="USD",K40*$E$3,K40) -> 15 | M40: =L40/$L$38 -> 1.2 | AI40: =IFERROR(X40/Q40,"-") -> - | AJ40: =IFERROR(X40/P40,"-") -> -
B41: Alpha I's 6th deal | L41: =L42 -> 12.5 | AI41: =IFERROR(X41/Q41,"-") -> - | AJ41: =IFERROR(X41/P41,"-") -> -
C42: Alpha's 5th deal | E42: 46054 | F42: =YEAR(E42) -> 2026 | G42: Vintage II | H42: Shift Alpha I | I42: R$ | K42: 12.5 | L42: =IF(I42="USD",K42*$E$3,K42) -> 12.5 | M42: =L42/$L$41 -> 1
...

Sheet 3- Support - FX rate
A1: Factset Price History: USDBRL
A3: Date | B3: Mid | C3: Change | D3: % Change | E3: Cumulative Change % | F3: High | G3: Low
A4: 45870 | B4: 5.4281 | C4: -0.17045 | D4: -3.0445383 | E4: 36.317633 | F4: 5.549 | G4: 5.39205
A5: 45839 | B5: 5.59855 | C5: 0.1407 | D5: 2.5779382 | E5: 40.598199 | F5: 5.60465 | G5: 5.40675
A6: 45809 | B6: 5.45785 | C6: -0.2742 | D6: -4.7836289 | E6: 37.064755 | F6: 5.6883 | G6: 5.45785
A7: 45778 | B7: 5.73205 | C7: 0.07065 | D7: 1.2479245 | E7: 43.950828 | F7: 5.74015 | G7: 5.6146
A8: 45748 | B8: 5.6614 | C8: -0.06625 | D8: -1.1566698 | E8: 42.176572 | F8: 6.06325 | G8: 5.59675
A9: 45717 | B9: 5.72765 | C9: -0.14085 | D9: -2.4001022 | E9: 43.840329 | F9: 5.88765 | G9: 5.65005
A10: 45689 | B10: 5.8685 | C10: 0.027 | D10: 0.46221005 | E10: 47.377541 | F10: 5.8685 | G10: 5.6798
A11: 45658 | B11: 5.8415 | C11: -0.33635 | D11: -5.4444507 | E11: 46.699481 | F11: 6.1867 | G11: 5.8415
A12: 45627 | B12: 6.17785 | C12: 0.2072 | D12: 3.4703089 | E12: 55.146348 | F12: 6.2236 | G12: 5.972
A13: 45597 | B13: 5.97065 | C13: 0.1819 | D13: 3.1423019 | E13: 49.942867 | F13: 5.993 | G13: 5.6772
A14: 45566 | B14: 5.78875 | C14: 0.34295 | D14: 6.2975137 | E14: 45.374754 | F14: 5.78875 | G14: 5.4341
A15: 45536 | B15: 5.4458 | C15: -0.2175 | D15: -3.840517 | E15: 36.762139 | F15: 5.6694 | G15: 5.42435
... A90: 43252 | B90: 3.8474 | C90: 0.12335 | D90: 3.3122541 | E90: -3.3789977 | F90: 3.88975 | G90: 3.6774
